Workbook

Sheet ★보고서
C3: 여남동 일일현황보고 | H3: 신용산 | J3: 점 | N3: ='0.기초및고정비'!C4 -> 2026년 | P3: 4 | Q3: 26 | S3: 월 영업일 | U3: ='0.기초및고정비'!E4 -> 30
C5: 목표 매출액 | E5: ='0.기초및고정비'!G4 -> 0 | G5: 달성율 | H5: =IFERROR(E6/E5,0) -> 0 | K5: 손 익 현 황 | N5: 당일 | Q5: =IFERROR(N6/F9,0) -> 0.048522865 | R5: 월 누적 | U5: =IFERROR(R6/H9,0) -> 0.30043296
C6: 월 누적매출액 | E6: =H9 -> 82874500 | N6: =F9-N9 -> 117425.33 | R6: =H9-R9 -> 24898231
C8: 수 입 합 계 | F8: 당일 | H8: 월 누적 | K8: 지 출 합 계 | N8: 당일 | R8: 월 누적
F9: =SUM(F10:G15) -> 2420000 | H9: =SUM(H10:I15) -> 82874500 | N9: =SUM(N10:P29)+O30+O48+SUM(N50:P71) -> 2302574.7 | Q9: =IFERROR(N9/F9,0) -> 0.95147713 | R9: =SUM(R10:T29)+S30+S48+SUM(R50:T71) -> 57976269 | U9: =IFERROR(R9/H9,0) -> 0.69956704
C10: 순매출액 | D10: 카드매출 | F10: =IFERROR(VLOOKUP($Q$3,'1.매출'!$A$5:$Y$35,5,0),0) -> 2362000 | H10: ='1.매출'!F36 -> 73220500 | K10: 원재료 | L10: 식자재 | M10: ='3.원,부재료'!C5 -> 청정 | N10: =IFERROR(VLOOKUP($Q$3,'3.원,부재료'!$A$7:$S$37,3,0),0) -> 0 | Q10: =IFERROR(N10/$F$9,0) -> 0 | R10: ='3.원,부재료'!C38 -> 5889634 | U10: =IFERROR(R10/$H$9,0) -> 0.071066902 | V10: =SUM(U10:U23) -> 0.29058437
D12: 현금매출 | F12: =IFERROR(VLOOKUP($Q$3,'1.매출'!$A$5:$Y$35,7,0),0) -> 58000 | H12: ='1.매출'!G36 -> 5568000 | L12: 수산 | M12: ='3.원,부재료'!D5 -> 오대양 | N12: =IFERROR(VLOOKUP($Q$3,'3.원,부재료'!$A$7:$S$37,4,0),0) -> 1149300 | Q12: =IFERROR(N12/$F$9,0) -> 0.47491736 | R12: ='3.원,부재료'!D38 -> 14969150 | U12: =IFERROR(R12/$H$9,0) -> 0.18062432
D14: 배달/기타/페이매출 | F14: =IFERROR(VLOOKUP($Q$3,'1.매출'!$A$5:$Y$35,14,0),0)+IFERROR(VLOOKUP($Q$3,'1.매출'!$A$5:$Y$35,18,0),0) -> 0 | H14: ='1.매출'!N36+'1.매출'!R36 -> 4086000 | L14: 기타식자재 | M14: 다수 | N14: =IFERROR(VLOOKUP($Q$3,'3.원,부재료'!$A$7:$S$37,5,0),0)+IFERROR(VLOOKUP($Q$3,'3.원,부재료'!$A$7:$S$37,6,0),0)+IFERROR(VLOOKUP($Q$3,'3.원,부재료'!$A$7:$S$37,7,0),0)+IFERROR(VLOOKUP($Q$3,'3.원,부재료'!$A$7:$S$37,8,0),0)+IFERROR(VLOOKUP($Q$3,'3.원,부재료'!$A$7:$S$37,9,0),0) -> 0 | Q14: =IFERROR(N14/$F$9,0) -> 0 | R14: ='3.원,부재료'!E38+'3.원,부재료'!F38+'3.원,부재료'!G38+'3.원,부재료'!H38+'3.원,부재료'!I38 -> 2021700 | U14: =IFERROR(R14/$H$9,0) -> 0.024394717
D16: 할 인 | F16: =-IFERROR(VLOOKUP($Q$3,'1.매출'!$A$5:$Y$35,9,0),0) -> 0 | H16: =-'1.매출'!I36 -> 0 | L16: 데일리 체크 | M16: ='3.원,부재료'!O4 -> 0 | N16: =IFERROR(VLOOKUP($Q$3,'3.원,부재료'!$A$7:$S$37,15,0),0) -> 0 | Q16: =IFERROR(N16/$F$9,0) -> 0 | R16: ='3.원,부재료'!O38 -> 0 | U16: =IFERROR(R16/$H$9,0) -> 0
D18: 서비스 | F18: =-VLOOKUP($Q$3,'1.매출'!$A$5:$P$35,10,0) -> 0 | H18: =-'1.매출'!J36 -> 0 | M18: ='3.원,부재료'!P4 -> 0 | N18: =IFERROR(VLOOKUP($Q$3,'3.원,부재료'!$A$7:$S$37,16,0),0) -> 0 | Q18: =IFERROR(N18/$F$9,0) -> 0 | R18: ='3.원,부재료'!P38 -> 0 | U18: =IFERROR(R18/$H$9,0) -> 0
L20: 본사구매 | N20: =IFERROR(VLOOKUP($Q$3,'3.원,부재료'!$A$7:$S$37,18,0),0) -> 0 | Q20: =IFERROR(N20/$F$9,0) -> 0 | R20: ='3.원,부재료'!R38 -> 858950 | U20: =IFERROR(R20/$H$9,0) -> 0.010364467
C21: 품목별 매출 | D21: 메뉴 | F21: =VLOOKUP($Q$3,'1.매출'!$A$5:$Y$35,20,0)+VLOOKUP($Q$3,'1.매출'!$A$5:$Y$35,21,0)+VLOOKUP($Q$3,'1.매출'!$A$5:$Y$35,22,0) -> 0 | H21: ='1.매출'!T36+'1.매출'!U36+'1.매출'!V36 -> 0
L22: 현장구매(카드/시재) | N22: =IFERROR(VLOOKUP($Q$3,'3.원,부재료'!$A$7:$S$37,19,0),0) -> 0 | Q22: =IFERROR(N22/$F$9,0) -> 0 | R22: ='3.원,부재료'!S38 -> 342600 | U22: =IFERROR(R22/$H$9,0) -> 0.0041339616
D23: 주류 | F23: =VLOOKUP($Q$3,'1.매출'!$A$5:$Y$35,23,0)+VLOOKUP($Q$3,'1.매출'!$A$5:$Y$35,24,0) -> 0 | H23: ='1.매출'!W36+'1.매출'!X36 -> 0
K24: 부재료 | L24: 주류 | N24: =IFERROR(VLOOKUP($Q$3,'3.원,부재료'!$A$7:$S$37,10,0),0) -> 0 | Q24: =IFERROR(N24/$F$9,0) -> 0 | R24: ='3.원,부재료'!J38 -> 4750210 | U24: =IFERROR(R24/$H$9,0) -> 0.057318114 | V24: =SUM(U24:U29) -> 0.061601699
D25: 기타 | F25: =IFERROR(VLOOKUP($Q$3,'1.매출'!$A$5:$Y$35,25,0),0) -> 0 | H25: ='1.매출'!Y36 -> 0
L26: 음료 | N26: =IFERROR(VLOOKUP($Q$3,'3.원,부재료'!$A$7:$S$37,13,0),0) -> 0 | Q26: =IFERROR(N26/$F$9,0) -> 0 | R26: ='3.원,부재료'!M38 -> 355000 | U26: =IFERROR(R26/$H$9,0) -> 0.0042835854
C28: 고객정보 | D28: 영수건수 | F28: =VLOOKUP($Q$3,'1.매출'!$A$5:$Y$35,11,0) -> 20 | H28: ='1.매출'!K36 -> 643 | L28: 기타주류 등 | N28: =IFERROR(VLOOKUP($Q$3,'3.원,부재료'!$A$7:$S$37,11,0),0)+IFERROR(VLOOKUP($Q$3,'3.원,부재료'!$A$7:$S$37,12,0),0) -> 0 | Q28: =IFERROR(N28/$F$9,0) -> 0 | R28: ='3.원,부재료'!K38+'3.원,부재료'!L38 -> 0 | U28: =IFERROR(R28/$H$9,0) -> 0
D30: 고객수 | F30: =IFERROR(VLOOKUP($Q$3,'1.매출'!$A$5:$Y$35,12,0),0) -> 20 | H30: ='1.매출'!L36 -> 613 | K30: 인건비 | L30: 정직원 | M30: 근무 | N30: =IFERROR(HLOOKUP($Q$3,'2-2.근무표'!$F$50:$AK$59,2,0),0) -> 4 | O30: =IFERROR(HLOOKUP($Q$3,'2-2.근무표'!$G$62:$AK$84,23,0),0) -> 625076.33 | Q30: =IFERROR(O30/$F$9,0) -> 0.25829601 | R30: =COUNTA('2-1.직원현황'!C5:C14) -> 3 | S30: ='2-2.근무표'!AL84 -> 14891985 | U30: =IFERROR(S30/$H$9,0) -> 0.17969321 | V30: =SUM(U30:U49) -> 0.25566953
D32: 테이블 단가 | F32: =IFERROR(F9/F28,0) -> 121000 | H32: =IFERROR(H9/H28,0) -> 128887.25 | M32: 휴무 | N32: =IFERROR(HLOOKUP($Q$3,'2-2.근무표'!$F$50:$AK$59,3,0),0) -> 0
M34: 월차/반차 | N34: =IFERROR(HLOOKUP($Q$3,'2-2.근무표'!$F$50:$AK$59,4,0),0) -> 1
C35: 현금시재 | D35: =IFERROR(VLOOKUP($Q$3,'6.마감사항'!$A$6:$I$36,2,0),0) -> 0
M36: 무단무급 | N36: =IFERROR(HLOOKUP($Q$3,'2-2.근무표'!$F$50:$AK$59,5,0),0) -> 0
D37: 십만원 | E37: 오만원 | F37: 만원 | G37: 오천원 | H37: 천원 | I37: 오백원/백원
M38: 권장휴무 | N38: =IFERROR(HLOOKUP($Q$3,'2-2.근무표'!$F$50:$AK$59,6,0),0) -> 0
D39: =VLOOKUP($Q$3,'6.마감사항'!$A$6:$S$36,3,0) -> 0 | E39: =VLOOKUP($Q$3,'6.마감사항'!$A$6:$S$36,4,0) -> 0 | F39: =VLOOKUP($Q$3,'6.마감사항'!$A$6:$S$36,5,0) -> 0 | G39: =VLOOKUP($Q$3,'6.마감사항'!$A$6:$S$36,6,0) -> 0 | H39: =VLOOKUP($Q$3,'6.마감사항'!$A$6:$S$36,7,0) -> 0 | I39: =VLOOKUP($Q$3,'6.마감사항'!$A$6:$S$36,8,0)+VLOOKUP($Q$3,'6.마감사항'!$A$6:$S$36,9,0) -> 0
M40: 예비군/민방위 | N40: =IFERROR(HLOOKUP($Q$3,'2-2.근무표'!$F$50:$AK$59,7,0),0) -> 0
C42: ※ 특이사항 | M42: 지원 | N42: =IFERROR(HLOOKUP($Q$3,'2-2.근무표'!$F$50:$AK$59,8,0),0) -> 0
C44: 구 분 | D44: 고객 | F44: 원재료/비품 | H44: 직원 | M44: 파견 | N44: =IFERROR(HLOOKUP($Q$3,'2-2.근무표'!$F$50:$AK$59,9,0),0) -> 0
C46: 내용 | D46: =VLOOKUP($Q$3,'6.마감사항'!$A$6:$S$36,11,0) -> 0 | F46: =VLOOKUP($Q$3,'6.마감사항'!$A$6:$S$36,14,0) -> 0 | H46: =VLOOKUP($Q$3,'6.마감사항'!$A$6:$S$36,17,0) -> 0 | M46: 관리팀 | N46: =IFERROR(HLOOKUP($Q$3,'2-2.근무표'!$F$50:$AK$59,10,0),0) -> 0
L48: 파트타이머 | N48: =IFERROR(HLOOKUP($Q$3,'2-2.근무표'!$G$29:$AK$46,18,0),0) -> 2 | O48: =IFERROR(HLOOKUP($Q$3,'2-2.근무표'!$G$87:$AK$104,18,0),0) -> 330000 | Q48: =IFERROR(O48/$F$9,0) -> 0.13636364 | R48: =COUNTA('2-1.직원현황'!C31:C45) -> 6 | S48: ='2-2.근무표'!AL104 -> 6296500 | U48: =IFERROR(S48/$H$9,0) -> 0.075976326
K50: 카드/시재 | L50: 복리후생비 | N50: =IFERROR((VLOOKUP($Q$3,'5.법카,시재지출'!$A$6:$J$223,2,0)),0) -> 0 | Q50: =IFERROR(N50/$F$9,0) -> 0 | R50: ='5.법카,시재지출'!B223 -> 0 | U50: =IFERROR(R50/$H$9,0) -> 0 | V50: =SUM(U50:U55) -> 0.012567798
L52: 비품 등 | N52: =IFERROR((VLOOKUP($Q$3,'5.법카,시재지출'!$A$6:$J$223,3,0)),0)+IFERROR((VLOOKUP($Q$3,'5.법카,시재지출'!$A$6:$J$223,6,0)),0) -> 0 | Q52: =IFERROR(N52/$F$9,0) -> 0 | R52: ='5.법카,시재지출'!C223+'5.법카,시재지출'!F223 -> 1034250 | U52: =IFERROR(R52/$H$9,0) -> 0.012479713
L54: 교통비 | N54: =IFERROR((VLOOKUP($Q$3,'5.법카,시재지출'!$A$6:$J$223,4,0)),0) -> 0 | Q54: =IFERROR(N54/$F$9,0) -> 0 | R54: ='5.법카,시재지출'!D223 -> 7300 | U54: =IFERROR(R54/$H$9,0) -> 8.8084996e-05
K56: 본사지출 | L56: 집기/설비/수리 등 | N56: =IFERROR((VLOOKUP($Q$3,※계좌이체!$A$6:$E$191,3,0)),0) -> 0 | Q56: =IFERROR(N56/$F$9,0) -> 0 | R56: =※계좌이체!C192 -> 0 | U56: =IFERROR(R56/$H$9,0) -> 0 | V56: =SUM(U31:U57) -> 0.088544124
L58: 수수료/세금 등 | N58: =IFERROR((VLOOKUP($Q$3,※계좌이체!$A$6:$E$191,4,0)),0) -> 0 | Q58: =IFERROR(N58/$F$9,0) -> 0 | R58: =※계좌이체!D192 -> 0 | U58: =IFERROR(R58/$H$9,0) -> 0
C59: 처리 | D59: =VLOOKUP($Q$3,'6.마감사항'!$A$6:$S$36,12,0) -> 0 | F59: =VLOOKUP($Q$3,'6.마감사항'!$A$6:$S$36,15,0) -> 0 | H59: =VLOOKUP($Q$3,'6.마감사항'!$A$6:$S$36,18,0) -> 0
L60: 광고비 | N60: =IFERROR((VLOOKUP($Q$3,※계좌이체!$A$6:$E$191,5,0)),0) -> 0 | Q60: =IFERROR(N60/$F$9,0) -> 0 | R60: =※계좌이체!E192 -> 0 | U60: =IFERROR(R60/$H$9,0) -> 0
K62: 고정비 /기타 | L62: 임대료 | N62: ='0.기초및고정비'!E9/'0.기초및고정비'!E4 -> 83333.333 | Q62: =IFERROR(N62/$F$9,0) -> 0.034435262 | R62: ='0.기초및고정비'!E9/'0.기초및고정비'!E4*★보고서!Q3 -> 2166666.7 | U62: =IFERROR(R62/$H$9,0) -> 0.026143949 | V62: =SUM(U62:U71) -> 0.079143648
L64: 관리비(평균) | N64: =SUM('0.기초및고정비'!E10:E15)/'0.기초및고정비'!E4 -> 99333.333 | Q64: =IFERROR(N64/$F$9,0) -> 0.041046832 | R64: =SUM('0.기초및고정비'!E10:E15)/'0.기초및고정비'!E4*★보고서!Q3 -> 2582666.7 | U64: =IFERROR(R64/$H$9,0) -> 0.031163587
...

Sheet 0.기초및고정비
B1: ■ 매장 기본정보 입력 _ 매월초 | G1: 핑크색 부분만 작성
B3: 1. 매월 기초 세팅
B4: 당월 구분 | C4: 2026년 | D4: 4월 | E4: {=_xlfn.IFS(D4="1월","31",D4="2월","28",D4="3월","31",D4="4월","30",D4="5월","31",D4="6월","30",D4="7월","31",D4="8월","31",D4="9월","30",D4="10월","31",D4="11월","30",D4="12월","31")} -> 30 | F4: 당월목표
C5: ↑ 드롭다운 선택 | D5: ↑ 드롭다운 선택 | E5: 건드리지 말것 (해당월 일수)
B7: 2. 고정비1_임대료/관리비/주류대출(VAT포함 실 지출액)
B8: 비용구분 | C8: 업체명 | D8: 이체일 | E8: 설정금액 (평균기준) | F8: 실제금액 | G8: 계약기간 등 추가사항
B9: 임대료 | E9: 2500000 | I9: ←매달 금액변경 : 전월 기준 작성 후, 당월 실제 지출액으로 변경
B10: 도시가스 | I10: ←매달 금액변경 : 전월 기준 작성 후, 당월 실제 지출액으로 변경
B11: 전기료 | I11: ←매달 금액변경 : 전월 기준 작성 후, 당월 실제 지출액으로 변경
B12: 수도료 | I12: ←매달 금액변경 : 전월 기준 작성 후, 당월 실제 지출액으로 변경
B13: 건물관리비 | I13: ←매달 금액변경 : 전월 기준 작성 후, 당월 실제 지출액으로 변경
B14: 주류대출 | E14: 2980000
B17: 총 합 계 | E17: =SUM(E9:E16) -> 5480000 | F17: =SUM(F9:F16) -> 0
B19: 3. 고정비2_운영 月고정비(VAT포함 실 지출액)
B20: 비용구분 | C20: 업체명 | D20: 이체일 | E20: 설정금액 (평균기준) | F20: 실제금액 | G20: 계약기간 등 추가사항
B21: 화재보험
B22: 보안설비 | E22: 120000
B23: 방역
B24: 정수기 | E24: 18900
B25: 인터넷/전화 | E25: 39050 | I25: ←매달 금액변경 : 전월 기준 작성 후, 당월 실제 지출액으로 변경
B26: 인터넷/전화 | I26: ←매달 금액변경 : 전월 기준 작성 후, 당월 실제 지출액으로 변경
B27: POS
B28: 테이블오더 | E28: 288000
B29: SMS수수료
B30: 세무기장료
B31: 분리수거
B32: 캐치테이블
B34: 총 합 계 | E34: =SUM(E21:E33) -> 465950 | F34: =SUM(F21:F33) -> 0

Sheet 1.매출
A1: ■ 일간 매출 작성 | D1: ='0.기초및고정비'!C4&'0.기초및고정비'!D4 -> 2026년4월 | H1: 핑크색 부분만 작성
A3: 일자 | B3: 총매출액 | C3: 테이블단가 (배달포함) | D3: 매장 순매출 | E3: 카드 순매출 | F3: 카드매출 | G3: 현금매출 | I3: 할인/서비스 | K3: 영수건수/고객수 | M3: 배달매출 | O3: 계좌이체 | Q3: 캐치테이블 | T3: 판매품목별 매출 | AA3: 카드취소 특이사항 | AD3: 기타 특이사항 | AF3: 0.0192 | AG3: 0.213
G4: 현금매출액 | H4: 현금영수증 | I4: 할인액 | J4: 서비스액 | K4: 영수건수 | L4: 고객수 | M4: 배달건수 | N4: 배달매출 | O4: 이체건수 | P4: 이체금액 | Q4: 영수건수 | R4: 이체금액 | T4: 메뉴 | U4: 기타메뉴 | V4: 포장 | W4: 주류 | X4: 기타주류 | Y4: 기타 | AA4: 취소건수 | AB4: 취소액 | AC4: 취소사유 | AF4: 카드수수료(예상) | AG4: 배달수수료(예상)
A5: 1 | B5: =D5+N5 -> 1605000 | C5: =IFERROR((E5+G5+N5+R5)/(K5+M5),0) -> 114642.86 | D5: =E5+G5+R5 -> 1605000 | E5: =F5-R5 -> 1605000 | F5: 1605000 | K5: 14 | L5: 14 | AF5: =F5*$AF$3 -> 30816 | AG5: =N5*$AG$3 -> 0
A6: 2 | B6: =D6+N6 -> 2517000 | C6: =IFERROR((E6+G6+N6+R6)/(K6+M6),0) -> 139833.33 | D6: =E6+G6+R6 -> 2517000 | E6: =F6-R6 -> 2510000 | F6: 2510000 | G6: 7000 | K6: 18 | L6: 18 | AF6: =F6*$AF$3 -> 48192 | AG6: =N6*$AG$3 -> 0
A7: 3 | B7: =D7+N7 -> 2148000 | C7: =IFERROR((E7+G7+N7+R7)/(K7+M7),0) -> 107400 | D7: =E7+G7+R7 -> 2148000 | E7: =F7-R7 -> 2057000 | F7: 2057000 | G7: 91000 | K7: 20 | L7: 20 | AF7: =F7*$AF$3 -> 39494.4 | AG7: =N7*$AG$3 -> 0
A8: 4 | B8: =D8+N8 -> 3596000 | C8: =IFERROR((E8+G8+N8+R8)/(K8+M8),0) -> 102742.86 | D8: =E8+G8+R8 -> 3596000 | E8: =F8-R8 -> 3596000 | F8: 3596000 | K8: 35 | L8: 35 | AF8: =F8*$AF$3 -> 69043.2 | AG8: =N8*$AG$3 -> 0
A9: 5 | B9: =D9+N9 -> 1926000 | C9: =IFERROR((E9+G9+N9+R9)/(K9+M9),0) -> 113294.12 | D9: =E9+G9+R9 -> 1926000 | E9: =F9-R9 -> 1926000 | F9: 1926000 | K9: 17 | L9: 17 | AF9: =F9*$AF$3 -> 36979.2 | AG9: =N9*$AG$3 -> 0
A10: 6 | B10: =D10+N10 -> 930000 | C10: =IFERROR((E10+G10+N10+R10)/(K10+M10),0) -> 116250 | D10: =E10+G10+R10 -> 930000 | E10: =F10-R10 -> 930000 | F10: 930000 | K10: 8 | L10: 8 | AF10: =F10*$AF$3 -> 17856 | AG10: =N10*$AG$3 -> 0
A11: 7 | B11: =D11+N11 -> 991000 | C11: =IFERROR((E11+G11+N11+R11)/(K11+M11),0) -> 123875 | D11: =E11+G11+R11 -> 991000 | E11: =F11-R11 -> 809000 | F11: 809000 | G11: 182000 | K11: 8 | L11: 8 | O11: 1 | P11: 182000 | AF11: =F11*$AF$3 -> 15532.8 | AG11: =N11*$AG$3 -> 0
A12: 8 | B12: =D12+N12 -> 1152500 | C12: =IFERROR((E12+G12+N12+R12)/(K12+M12),0) -> 104772.73 | D12: =E12+G12+R12 -> 1152500 | E12: =F12-R12 -> 1152500 | F12: 1152500 | K12: 11 | L12: 11 | AF12: =F12*$AF$3 -> 22128 | AG12: =N12*$AG$3 -> 0
A13: 9 | B13: =D13+N13 -> 1736000 | C13: =IFERROR((E13+G13+N13+R13)/(K13+M13),0) -> 115733.33 | D13: =E13+G13+R13 -> 1736000 | E13: =F13-R13 -> 1318000 | F13: 1422000 | G13: 314000 | K13: 15 | L13: 15 | Q13: 1 | R13: 104000 | AF13: =F13*$AF$3 -> 27302.4 | AG13: =N13*$AG$3 -> 0
A14: 10 | B14: =D14+N14 -> 3513000 | C14: =IFERROR((E14+G14+N14+R14)/(K14+M14),0) -> 106454.55 | D14: =E14+G14+R14 -> 3513000 | E14: =F14-R14 -> 3513000 | F14: 3513000 | K14: 33 | L14: 33 | AF14: =F14*$AF$3 -> 67449.6 | AG14: =N14*$AG$3 -> 0
A15: 11 | B15: =D15+N15 -> 4591000 | C15: =IFERROR((E15+G15+N15+R15)/(K15+M15),0) -> 104340.91 | D15: =E15+G15+R15 -> 4591000 | E15: =F15-R15 -> 4066000 | F15: 4179000 | G15: 412000 | K15: 44 | L15: 44 | Q15: 1 | R15: 113000 | AF15: =F15*$AF$3 -> 80236.8 | AG15: =N15*$AG$3 -> 0
A16: 12 | B16: =D16+N16 -> 3656000 | C16: =IFERROR((E16+G16+N16+R16)/(K16+M16),0) -> 121866.67 | D16: =E16+G16+R16 -> 3656000 | E16: =F16-R16 -> 3106000 | F16: 3381000 | G16: 275000 | K16: 30 | L16: 30 | Q16: 1 | R16: 275000 | AF16: =F16*$AF$3 -> 64915.2 | AG16: =N16*$AG$3 -> 0
A17: 13 | B17: =D17+N17 -> 703000 | C17: =IFERROR((E17+G17+N17+R17)/(K17+M17),0) -> 70300 | D17: =E17+G17+R17 -> 703000 | E17: =F17-R17 -> 677000 | F17: 677000 | G17: 26000 | K17: 10 | L17: 10 | AF17: =F17*$AF$3 -> 12998.4 | AG17: =N17*$AG$3 -> 0
A18: 14 | B18: =D18+N18 -> 2931000 | C18: =IFERROR((E18+G18+N18+R18)/(K18+M18),0) -> 146550 | D18: =E18+G18+R18 -> 2931000 | E18: =F18-R18 -> 2643000 | F18: 2744000 | G18: 187000 | K18: 20 | L18: 20 | Q18: 1 | R18: 101000 | AF18: =F18*$AF$3 -> 52684.8 | AG18: =N18*$AG$3 -> 0
A19: 15 | B19: =D19+N19 -> 3600000 | C19: =IFERROR((E19+G19+N19+R19)/(K19+M19),0) -> 120000 | D19: =E19+G19+R19 -> 3600000 | E19: =F19-R19 -> 3105000 | F19: 3401000 | G19: 199000 | K19: 30 | Q19: 3 | R19: 296000 | AF19: =F19*$AF$3 -> 65299.2 | AG19: =N19*$AG$3 -> 0
A20: 16 | B20: =D20+N20 -> 3674000 | C20: =IFERROR((E20+G20+N20+R20)/(K20+M20),0) -> 146960 | D20: =E20+G20+R20 -> 3674000 | E20: =F20-R20 -> 3204000 | F20: 3439000 | G20: 235000 | K20: 25 | L20: 25 | Q20: 1 | R20: 235000 | AF20: =F20*$AF$3 -> 66028.8 | AG20: =N20*$AG$3 -> 0
A21: 17 | B21: =D21+N21 -> 5930000 | C21: =IFERROR((E21+G21+N21+R21)/(K21+M21),0) -> 152051.28 | D21: =E21+G21+R21 -> 5930000 | E21: =F21-R21 -> 4154000 | F21: 5042000 | G21: 888000 | K21: 39 | L21: 39 | Q21: 3 | R21: 888000 | AF21: =F21*$AF$3 -> 96806.4 | AG21: =N21*$AG$3 -> 0
A22: 18 | B22: =D22+N22 -> 5736500 | C22: =IFERROR((E22+G22+N22+R22)/(K22+M22),0) -> 139914.63 | D22: =E22+G22+R22 -> 5736500 | E22: =F22-R22 -> 4404500 | F22: 5005500 | G22: 731000 | H22: 130000 | K22: 41 | L22: 41 | Q22: 4 | R22: 601000 | AF22: =F22*$AF$3 -> 96105.6 | AG22: =N22*$AG$3 -> 0
A23: 19 | B23: =D23+N23 -> 3008000 | C23: =IFERROR((E23+G23+N23+R23)/(K23+M23),0) -> 120320 | D23: =E23+G23+R23 -> 3008000 | E23: =F23-R23 -> 2876000 | F23: 2942000 | G23: 66000 | K23: 25 | L23: 25 | Q23: 1 | R23: 66000 | AF23: =F23*$AF$3 -> 56486.4 | AG23: =N23*$AG$3 -> 0
A24: 20 | B24: =D24+N24 -> 2021000 | C24: =IFERROR((E24+G24+N24+R24)/(K24+M24),0) -> 112277.78 | D24: =E24+G24+R24 -> 2021000 | E24: =F24-R24 -> 1995000 | F24: 1995000 | G24: 26000 | K24: 18 | L24: 18 | AF24: =F24*$AF$3 -> 38304 | AG24: =N24*$AG$3 -> 0
A25: 21 | B25: =D25+N25 -> 2899500 | C25: =IFERROR((E25+G25+N25+R25)/(K25+M25),0) -> 144975 | D25: =E25+G25+R25 -> 2899500 | E25: =F25-R25 -> 2152500 | F25: 2457500 | G25: 442000 | K25: 20 | L25: 20 | Q25: 1 | R25: 305000 | AF25: =F25*$AF$3 -> 47184 | AG25: =N25*$AG$3 -> 0
A26: 22 | B26: =D26+N26 -> 3592000 | C26: =IFERROR((E26+G26+N26+R26)/(K26+M26),0) -> 112250 | D26: =E26+G26+R26 -> 3592000 | E26: =F26-R26 -> 3127000 | F26: 3238000 | G26: 354000 | K26: 32 | L26: 32 | Q26: 1 | R26: 111000 | AF26: =F26*$AF$3 -> 62169.6 | AG26: =N26*$AG$3 -> 0
A27: 23 | B27: =D27+N27 -> 2810000 | C27: =IFERROR((E27+G27+N27+R27)/(K27+M27),0) -> 127727.27 | D27: =E27+G27+R27 -> 2810000 | E27: =F27-R27 -> 2810000 | F27: 2810000 | K27: 22 | L27: 22 | AF27: =F27*$AF$3 -> 53952 | AG27: =N27*$AG$3 -> 0
A28: 24 | B28: =D28+N28 -> 4721000 | C28: =IFERROR((E28+G28+N28+R28)/(K28+M28),0) -> 107295.45 | D28: =E28+G28+R28 -> 4721000 | E28: =F28-R28 -> 4117000 | F28: 4377000 | G28: 344000 | K28: 44 | L28: 44 | Q28: 1 | R28: 260000 | AF28: =F28*$AF$3 -> 84038.4 | AG28: =N28*$AG$3 -> 0
A29: 25 | B29: =D29+N29 -> 6381000 | C29: =IFERROR((E29+G29+N29+R29)/(K29+M29),0) -> 145022.73 | D29: =E29+G29+R29 -> 6381000 | E29: =F29-R29 -> 4919000 | F29: 5650000 | G29: 731000 | K29: 44 | L29: 44 | Q29: 5 | R29: 731000 | AF29: =F29*$AF$3 -> 108480 | AG29: =N29*$AG$3 -> 0
A30: 26 | B30: =D30+N30 -> 2420000 | C30: =IFERROR((E30+G30+N30+R30)/(K30+M30),0) -> 121000 | D30: =E30+G30+R30 -> 2420000 | E30: =F30-R30 -> 2362000 | F30: 2362000 | G30: 58000 | K30: 20 | L30: 20 | AF30: =F30*$AF$3 -> 45350.4 | AG30: =N30*$AG$3 -> 0
A31: 27 | B31: =D31+N31 -> 0 | C31: =IFERROR((E31+G31+N31+R31)/(K31+M31),0) -> 0 | D31: =E31+G31+R31 -> 0 | E31: =F31-R31 -> 0 | AF31: =F31*$AF$3 -> 0 | AG31: =N31*$AG$3 -> 0
A32: 28 | B32: =D32+N32 -> 0 | C32: =IFERROR((E32+G32+N32+R32)/(K32+M32),0) -> 0 | D32: =E32+G32+R32 -> 0 | E32: =F32-R32 -> 0 | AF32: =F32*$AF$3 -> 0 | AG32: =N32*$AG$3 -> 0
A33: 29 | B33: =D33+N33 -> 0 | C33: =IFERROR((E33+G33+N33+R33)/(K33+M33),0) -> 0 | D33: =E33+G33+R33 -> 0 | E33: =F33-R33 -> 0 | AF33: =F33*$AF$3 -> 0 | AG33: =N33*$AG$3 -> 0
A34: 30 | B34: =D34+N34 -> 0 | C34: =IFERROR((E34+G34+N34+R34)/(K34+M34),0) -> 0 | D34: =E34+G34+R34 -> 0 | E34: =F34-R34 -> 0 | AF34: =F34*$AF$3 -> 0 | AG34: =N34*$AG$3 -> 0
A35: 31 | B35: =D35+N35 -> 0 | C35: =IFERROR((E35+G35+N35+R35)/(K35+M35),0) -> 0 | D35: =E35+G35+R35 -> 0 | E35: =F35-R35 -> 0 | AF35: =F35*$AF$3 -> 0 | AG35: =N35*$AG$3 -> 0
A36: 합 계 | B36: =SUM(B5:B35) -> 78788500 | C36: =IFERROR(B36/(K36+M36),0) -> 122532.66 | D36: =SUM(D5:D35) -> 78788500 | E36: =SUM(E5:E35) -> 69134500 | F36: =SUM(F5:F35) -> 73220500 | G36: =SUM(G5:G35) -> 5568000 | H36: =SUM(H5:H35) -> 130000 | I36: =SUM(I5:I35) -> 0 | J36: =SUM(J5:J35) -> 0 | K36: =SUM(K5:K35) -> 643 | ... R36: =SUM(R5:R35) -> 4086000 | T36: =SUM(T5:T35) -> 0 | U36: =SUM(U5:U35) -> 0 | V36: =SUM(V5:V35) -> 0 | W36: =SUM(W5:W35) -> 0 | X36: =SUM(X5:X35) -> 0 | Y36: =SUM(Y5:Y35) -> 0 | AA36: =SUM(AA5:AA35) -> 0 | AB36: =SUM(AB5:AB35) -> 0 | AF36: =SUM(AF5:AF35) -> 1405833.6 | AG36: =SUM(AG5:AG35) -> 0

Sheet 2-1.직원현황
B1: ■ 근로자 현황 | D1: 핑크색 부분만 작성
B3: 1.근로자 현황_정직원(4대보험_고정근로자) | U3: 0.03595 | V3: 0.1314 | W3: 0.0475 | X3: 0.009
B4: 구분 | C4: 이름 | D4: 근무파트 | E4: 직책 | F4: 입사일 | G4: 퇴사일 | H4: 근무조건 | I4: 신고방법 | J4: 연락처 | K4: 주민번호 | L4: 급여계좌 | N4: 월급여 필수기록!! (숫자만 입력) | P4: 과세대상급여 (직책수당포함) | Q4: 식대 | R4: 차량유지 | S4: 총급여 (직책수당포함) | U4: 건강보험 | V4: 장기요양 | W4: 국민연금 | X4: 고용보험 | Y4: 4대보험 사용자分 합계 | AA4: 4대보험포함 총 급 여
B5: 고정근로자 | C5: 박성배 | D5: 선택 | E5: 주방 | F5: 46022 | H5: 주1회휴무 | I5: 4대보험 | J5: 010-9211-1544 | K5: 900415-1095615 | L5: 카카오 3333 13012 1594 | N5: 3600000 | P5: =N5-200000 -> 3400000 | Q5: 200000 | S5: =P5+Q5+R5 -> 3600000 | U5: =TRUNC(P5*$U$3,-1) -> 122230 | V5: =TRUNC(U5*$V$3,-1) -> 16060 | W5: =TRUNC(P5*$W$3,-1) -> 161500 | X5: =TRUNC(P5*$X$3,-1) -> 30600 | Y5: =SUM(U5:X5) -> 330390 | AA5: =S5+Y5 -> 3930390
C6: 박참이 | D6: 선택 | E6: 주방 | F6: 46113 | H6: 월6회휴무 | I6: 4대보험 | J6: 010-4320-6101 | K6: 880226-2030625 | L6: 신한 110 262 594987 | N6: 3400000 | P6: =N6-200000 -> 3200000 | Q6: 200000 | S6: =P6+Q6+R6 -> 3400000 | U6: =TRUNC(P6*$U$3,-1) -> 115040 | V6: =TRUNC(U6*$V$3,-1) -> 15110 | W6: =TRUNC(P6*$W$3,-1) -> 152000 | X6: =TRUNC(P6*$X$3,-1) -> 28800 | Y6: =SUM(U6:X6) -> 310950 | AA6: =S6+Y6 -> 3710950
C7: 이건호 | D7: 선택 | E7: 홀 | F7: 46113 | H7: 월6회휴무 | I7: 4대보험 | J7: 010-7602-3858 | K7: 960527-1491016 | L7: 국민 510002 01 241497 | N7: 3400000 | P7: =N7-200000 -> 3200000 | Q7: 200000 | S7: =P7+Q7+R7 -> 3400000 | U7: =TRUNC(P7*$U$3,-1) -> 115040 | V7: =TRUNC(U7*$V$3,-1) -> 15110 | W7: =TRUNC(P7*$W$3,-1) -> 152000 | X7: =TRUNC(P7*$X$3,-1) -> 28800 | Y7: =SUM(U7:X7) -> 310950 | AA7: =S7+Y7 -> 3710950
D8: 선택 | I8: 4대보험 | P8: =N8-200000 -> -200000 | Q8: 200000 | S8: =P8+Q8+R8 -> 0 | U8: =TRUNC(P8*$U$3,-1) -> -7190 | V8: =TRUNC(U8*$V$3,-1) -> -940 | W8: =TRUNC(P8*$W$3,-1) -> -9500 | X8: =TRUNC(P8*$X$3,-1) -> -1800 | Y8: =SUM(U8:X8) -> -19430 | AA8: =S8+Y8 -> -19430
D9: 선택 | I9: 4대보험 | P9: =N9-200000 -> -200000 | Q9: 200000 | S9: =P9+Q9+R9 -> 0 | U9: =TRUNC(P9*$U$3,-1) -> -7190 | V9: =TRUNC(U9*$V$3,-1) -> -940 | W9: =TRUNC(P9*$W$3,-1) -> -9500 | X9: =TRUNC(P9*$X$3,-1) -> -1800 | Y9: =SUM(U9:X9) -> -19430 | AA9: =S9+Y9 -> -19430
D10: 선택 | I10: 4대보험 | P10: =N10-200000 -> -200000 | Q10: 200000 | S10: =P10+Q10+R10 -> 0 | U10: =TRUNC(P10*$U$3,-1) -> -7190 | V10: =TRUNC(U10*$V$3,-1) -> -940 | W10: =TRUNC(P10*$W$3,-1) -> -9500 | X10: =TRUNC(P10*$X$3,-1) -> -1800 | Y10: =SUM(U10:X10) -> -19430 | AA10: =S10+Y10 -> -19430
D11: 선택 | I11: 4대보험 | P11: =N11-200000 -> -200000 | Q11: 200000 | S11: =P11+Q11+R11 -> 0 | U11: =TRUNC(P11*$U$3,-1) -> -7190 | V11: =TRUNC(U11*$V$3,-1) -> -940 | W11: =TRUNC(P11*$W$3,-1) -> -9500 | X11: =TRUNC(P11*$X$3,-1) -> -1800 | Y11: =SUM(U11:X11) -> -19430 | AA11: =S11+Y11 -> -19430
D12: 선택 | I12: 4대보험 | P12: =N12-200000 -> -200000 | Q12: 200000 | S12: =P12+Q12+R12 -> 0 | U12: =TRUNC(P12*$U$3,-1) -> -7190 | V12: =TRUNC(U12*$V$3,-1) -> -940 | W12: =TRUNC(P12*$W$3,-1) -> -9500 | X12: =TRUNC(P12*$X$3,-1) -> -1800 | Y12: =SUM(U12:X12) -> -19430 | AA12: =S12+Y12 -> -19430
D13: 선택 | I13: 4대보험 | P13: =N13-200000 -> -200000 | Q13: 200000 | S13: =P13+Q13+R13 -> 0 | U13: =TRUNC(P13*$U$3,-1) -> -7190 | V13: =TRUNC(U13*$V$3,-1) -> -940 | W13: =TRUNC(P13*$W$3,-1) -> -9500 | X13: =TRUNC(P13*$X$3,-1) -> -1800 | Y13: =SUM(U13:X13) -> -19430 | AA13: =S13+Y13 -> -19430
D14: 선택 | I14: 4대보험 | P14: =N14-200000 -> -200000 | Q14: 200000 | S14: =P14+Q14+R14 -> 0 | U14: =TRUNC(P14*$U$3,-1) -> -7190 | V14: =TRUNC(U14*$V$3,-1) -> -940 | W14: =TRUNC(P14*$W$3,-1) -> -9500 | X14: =TRUNC(P14*$X$3,-1) -> -1800 | Y14: =SUM(U14:X14) -> -19430 | AA14: =S14+Y14 -> -19430
B16: 1-1.근로자 현황_정직원(3.3%_고정근로자)
B17: 구분 | C17: 이름 | D17: 근무파트 | E17: 직책 | F17: 입사일 | G17: 퇴사일 | H17: 근무조건 | I17: 신고방법 | J17: 연락처 | K17: 주민번호 | L17: 급여계좌 | N17: 월급여 필수기록!! (숫자만 입력)
B18: 고정근로자 | C18: 김지용 | D18: 선택 | F18: 46113 | I18: 0.033 | L18: 신한 110 431 372066 | N18: 4000000 | P18: =N18 -> 4000000 | S18: =P18+Q18+R18 -> 4000000 | AA18: =S18+Y18 -> 4000000
C19: 이도형 | D19: 선택 | F19: 46125 | I19: 0.033 | N19: 3400000 | P19: =N19 -> 3400000 | S19: =P19+Q19+R19 -> 3400000 | AA19: =S19+Y19 -> 3400000
D20: 선택 | I20: 0.033 | P20: =N20 -> 0 | S20: =P20+Q20+R20 -> 0 | AA20: =S20+Y20 -> 0
D21: 선택 | I21: 0.033 | P21: =N21 -> 0 | S21: =P21+Q21+R21 -> 0 | AA21: =S21+Y21 -> 0
D22: 선택 | I22: 0.033 | P22: =N22 -> 0 | S22: =P22+Q22+R22 -> 0 | AA22: =S22+Y22 -> 0
D23: 선택 | I23: 0.033 | P23: =N23 -> 0 | S23: =P23+Q23+R23 -> 0 | AA23: =S23+Y23 -> 0
D24: 선택 | I24: 0.033 | P24: =N24 -> 0 | S24: =P24+Q24+R24 -> 0 | AA24: =S24+Y24 -> 0
D25: 선택 | I25: 0.033 | P25: =N25 -> 0 | S25: =P25+Q25+R25 -> 0 | AA25: =S25+Y25 -> 0
D26: 선택 | I26: 0.033 | P26: =N26 -> 0 | S26: =P26+Q26+R26 -> 0 | AA26: =S26+Y26 -> 0
D27: 선택 | I27: 0.033 | P27: =N27 -> 0 | S27: =P27+Q27+R27 -> 0 | AA27: =S27+Y27 -> 0
B29: 2.근로자 현황_파트타이머
B30: 구분 | C30: 이름 | D30: 근무파트 | E30: 직책 | F30: 입사일 | G30: 퇴사일 | H30: 근무조건 | I30: 시급 | J30: 연락처 | K30: 주민번호 | L30: 급여계좌
B31: 파트타이머 | C31: 최은태 | D31: 주방 | E31: 파트타임 | I31: 20000 | K31: 800303-2637310 | L31: 경남 221 0110 1350 07
C32: 이서문 | D32: 선택 | E32: 파트타임 | I32: 13000 | K32: 960527-2471215 | L32: 카카오 3333 344 538401
C33: 김복순 | D33: 선택 | E33: 파트타임 | I33: 12000 | K33: 601109-6102493 | L33: 국민 424002 01 337949
C34: 이도형 | D34: 선택 | E34: 파트타임 | I34: 13000
C35: 송은비 | D35: 선택 | E35: 파트타임 | I35: 13000
C36: 김범창 | D36: 선택 | E36: 파트타임 | I36: 13000
D37: 선택 | E37: 파트타임
D38: 선택 | E38: 파트타임
D39: 선택 | E39: 파트타임
D40: 선택 | E40: 파트타임
D41: 선택 | E41: 파트타임
D42: 선택 | E42: 파트타임
D43: 선택 | E43: 파트타임
...

Sheet 2-2.근무표
B1: ■ 일간 근무표 작성 | E1: 핑크색 부분만 작성 | G1: ='0.기초및고정비'!C4&'0.기초및고정비'!D4 -> 2026년4월 | M1: ①정직원 근무현황 / ②알바근무현황 / ③직영관리팀 근무현황 3개다 꼭 작성!!!!!!
B3: ① 정직원 근무현황
B4: 이름 | C4: 파트 (홀/주방) | D4: 직책 | E4: 입사일 | F4: 퇴사일 (마지막근무일) | G4: 1 | H4: 2 | I4: 3 | J4: 4 | K4: 5 | L4: 6 | M4: 7 | N4: 8 | O4: 9 | P4: 10 | Q4: 11 | R4: 12 | S4: 13 | T4: 14 | U4: 15 | V4: 16 | W4: 17 | X4: 18 | Y4: 19 | Z4: 20 | AA4: 21 | AB4: 22 | AC4: 23 | AD4: 24 | AE4: 25 | AF4: 26 | AG4: 27 | AH4: 28 | AI4: 29 | AJ4: 30 | AK4: 31 | AL4: 월간 실근무일수 | AM4: 정기휴무 일수 | AN4: 월차/반차 일수 | AO4: 무단결근 | AP4: 무단조퇴 | AQ4: 권장휴무 | AR4: 권장조퇴 | AS4: 근무조건 | AU4: 연락처 | AV4: 주민번호 | AW4: 급여계좌 | AZ4: ='0.기초및고정비'!E4 -> 30
AY5: 월급(4대보험예상포함) | AZ5: 일급여
B6: ='2-1.직원현황'!C5 -> 박성배 | C6: ='2-1.직원현황'!D5 -> 선택 | D6: ='2-1.직원현황'!E5 -> 주방 | E6: ='2-1.직원현황'!F5 -> 46022 | F6: ='2-1.직원현황'!G5 -> 0 | G6: 근무 | H6: 근무 | I6: 근무 | J6: 근무 | K6: 휴무 | L6: 휴무 | M6: 근무 | N6: 근무 | O6: 근무 | P6: 근무 | Q6: 근무 | R6: 근무 | S6: 휴무 | T6: 근무 | U6: 근무 | V6: 근무 | W6: 근무 | X6: 근무 | Y6: 근무 | Z6: 근무 | AA6: 근무 | AB6: 근무 | AC6: 근무 | AD6: 휴무 | AE6: 휴무 | AF6: 월차 | AG6: - | AH6: - | AI6: - | AJ6: - | AK6: - | AL6: =COUNTIF(G6:AK6,"근무") -> 20 | AM6: =COUNTIF(G6:AK6,"휴무") -> 5 | AN6: =COUNTIF(G6:AK6,"월차")+COUNTIF(G6:AK6,"반차") -> 1 | AO6: =COUNTIF(G6:AK6,"무단결근") -> 0 | AP6: =COUNTIF(G6:AK6,"무단조퇴") -> 0 | AQ6: =COUNTIF(G6:AK6,"권장휴무") -> 0 | AR6: =COUNTIF(G6:AK6,"권장조퇴") -> 0 | AS6: ='2-1.직원현황'!H5 -> 주1회휴무 | AU6: ='2-1.직원현황'!J5 -> 010-9211-1544 | AV6: ='2-1.직원현황'!K5 -> 900415-1095615 | AW6: ='2-1.직원현황'!L5 -> 카카오 3333 13012 1594 | AY6: =IFERROR(VLOOKUP(B6,'2-1.직원현황'!$C$5:$AA$14,25,0),0) -> 3930390 | AZ6: =AY6/$AZ$4 -> 131013
B7: ='2-1.직원현황'!C6 -> 박참이 | C7: ='2-1.직원현황'!D6 -> 선택 | D7: ='2-1.직원현황'!E6 -> 주방 | E7: ='2-1.직원현황'!F6 -> 46113 | F7: ='2-1.직원현황'!G6 -> 0 | G7: 휴무 | H7: 근무 | I7: 근무 | J7: 근무 | K7: 근무 | L7: 근무 | M7: 근무 | N7: 휴무 | O7: 근무 | P7: 근무 | Q7: 근무 | R7: 근무 | S7: 근무 | T7: 휴무 | U7: 휴무 | V7: 근무 | W7: 근무 | X7: 근무 | Y7: 근무 | Z7: 근무 | AA7: 근무 | AB7: 휴무 | AC7: 근무 | AD7: 근무 | AE7: 근무 | AF7: 근무 | AG7: - | AH7: - | AI7: - | AJ7: - | AK7: - | AL7: =COUNTIF(G7:AK7,"근무") -> 21 | AM7: =COUNTIF(G7:AK7,"휴무") -> 5 | AN7: =COUNTIF(G7:AK7,"월차")+COUNTIF(G7:AK7,"반차") -> 0 | AO7: =COUNTIF(G7:AK7,"무단결근") -> 0 | AP7: =COUNTIF(G7:AK7,"무단조퇴") -> 0 | AQ7: =COUNTIF(G7:AK7,"권장휴무") -> 0 | AR7: =COUNTIF(G7:AK7,"권장조퇴") -> 0 | AS7: ='2-1.직원현황'!H6 -> 월6회휴무 | AU7: ='2-1.직원현황'!J6 -> 010-4320-6101 | AV7: ='2-1.직원현황'!K6 -> 880226-2030625 | AW7: ='2-1.직원현황'!L6 -> 신한 110 262 594987 | AY7: =IFERROR(VLOOKUP(B7,'2-1.직원현황'!$C$5:$AA$14,25,0),0) -> 3710950 | AZ7: =AY7/$AZ$4 -> 123698.33
B8: ='2-1.직원현황'!C7 -> 이건호 | C8: ='2-1.직원현황'!D7 -> 선택 | D8: ='2-1.직원현황'!E7 -> 홀 | E8: ='2-1.직원현황'!F7 -> 46113 | F8: ='2-1.직원현황'!G7 -> 0 | G8: 휴무 | H8: 근무 | I8: 근무 | J8: 근무 | K8: 근무 | L8: 근무 | M8: 근무 | N8: 근무 | O8: 휴무 | P8: 근무 | Q8: 근무 | R8: 근무 | S8: 근무 | T8: 근무 | U8: 휴무 | V8: 휴무 | W8: 근무 | X8: 근무 | Y8: 근무 | Z8: 근무 | AA8: 휴무 | AB8: 근무 | AC8: 근무 | AD8: 근무 | AE8: 근무 | AF8: 근무 | AG8: - | AH8: - | AI8: - | AJ8: - | AK8: - | AL8: =COUNTIF(G8:AK8,"근무") -> 21 | AM8: =COUNTIF(G8:AK8,"휴무") -> 5 | AN8: =COUNTIF(G8:AK8,"월차")+COUNTIF(G8:AK8,"반차") -> 0 | AO8: =COUNTIF(G8:AK8,"무단결근") -> 0 | AP8: =COUNTIF(G8:AK8,"무단조퇴") -> 0 | AQ8: =COUNTIF(G8:AK8,"권장휴무") -> 0 | AR8: =COUNTIF(G8:AK8,"권장조퇴") -> 0 | AS8: ='2-1.직원현황'!H7 -> 월6회휴무 | AU8: ='2-1.직원현황'!J7 -> 010-7602-3858 | AV8: ='2-1.직원현황'!K7 -> 960527-1491016 | AW8: ='2-1.직원현황'!L7 -> 국민 510002 01 241497 | AY8: =IFERROR(VLOOKUP(B8,'2-1.직원현황'!$C$5:$AA$14,25,0),0) -> 3710950 | AZ8: =AY8/$AZ$4 -> 123698.33
B9: ='2-1.직원현황'!C8 -> 0 | C9: ='2-1.직원현황'!D8 -> 선택 | D9: ='2-1.직원현황'!E8 -> 0 | E9: ='2-1.직원현황'!F8 -> 0 | F9: ='2-1.직원현황'!G8 -> 0 | G9: - | H9: - | I9: - | J9: - | K9: - | L9: - | M9: - | N9: - | O9: - | P9: - | Q9: - | R9: - | S9: - | T9: - | U9: - | V9: - | W9: - | X9: - | Y9: - | Z9: - | AA9: - | AB9: - | AC9: - | AD9: - | AE9: - | AF9: - | AG9: - | AH9: - | AI9: - | AJ9: - | AK9: - | AL9: =COUNTIF(G9:AK9,"근무") -> 0 | AM9: =COUNTIF(G9:AK9,"휴무") -> 0 | AN9: =COUNTIF(G9:AK9,"월차")+COUNTIF(G9:AK9,"반차") -> 0 | AO9: =COUNTIF(G9:AK9,"무단결근") -> 0 | AP9: =COUNTIF(G9:AK9,"무단조퇴") -> 0 | AQ9: =COUNTIF(G9:AK9,"권장휴무") -> 0 | AR9: =COUNTIF(G9:AK9,"권장조퇴") -> 0 | AS9: ='2-1.직원현황'!H8 -> 0 | AU9: ='2-1.직원현황'!J8 -> 0 | AV9: ='2-1.직원현황'!K8 -> 0 | AW9: ='2-1.직원현황'!L8 -> 0 | AY9: =IFERROR(VLOOKUP(B9,'2-1.직원현황'!$C$5:$AA$14,25,0),0) -> 0 | AZ9: =AY9/$AZ$4 -> 0
B10: ='2-1.직원현황'!C9 -> 0 | C10: ='2-1.직원현황'!D9 -> 선택 | D10: ='2-1.직원현황'!E9 -> 0 | E10: ='2-1.직원현황'!F9 -> 0 | F10: ='2-1.직원현황'!G9 -> 0 | G10: - | H10: - | I10: - | J10: - | K10: - | L10: - | M10: - | N10: - | O10: - | P10: - | Q10: - | R10: - | S10: - | T10: - | U10: - | V10: - | W10: - | X10: - | Y10: - | Z10: - | AA10: - | AB10: - | AC10: - | AD10: - | AE10: - | AF10: - | AG10: - | AH10: - | AI10: - | AJ10: - | AK10: - | AL10: =COUNTIF(G10:AK10,"근무") -> 0 | AM10: =COUNTIF(G10:AK10,"휴무") -> 0 | AN10: =COUNTIF(G10:AK10,"월차")+COUNTIF(G10:AK10,"반차") -> 0 | AO10: =COUNTIF(G10:AK10,"무단결근") -> 0 | AP10: =COUNTIF(G10:AK10,"무단조퇴") -> 0 | AQ10: =COUNTIF(G10:AK10,"권장휴무") -> 0 | AR10: =COUNTIF(G10:AK10,"권장조퇴") -> 0 | AS10: ='2-1.직원현황'!H9 -> 0 | AU10: ='2-1.직원현황'!J9 -> 0 | AV10: ='2-1.직원현황'!K9 -> 0 | AW10: ='2-1.직원현황'!L9 -> 0 | AY10: =IFERROR(VLOOKUP(B10,'2-1.직원현황'!$C$5:$AA$14,25,0),0) -> 0 | AZ10: =AY10/$AZ$4 -> 0
B11: ='2-1.직원현황'!C10 -> 0 | C11: ='2-1.직원현황'!D10 -> 선택 | D11: ='2-1.직원현황'!E10 -> 0 | E11: ='2-1.직원현황'!F10 -> 0 | F11: ='2-1.직원현황'!G10 -> 0 | G11: - | H11: - | I11: - | J11: - | K11: - | L11: - | M11: - | N11: - | O11: - | P11: - | Q11: - | R11: - | S11: - | T11: - | U11: - | V11: - | W11: - | X11: - | Y11: - | Z11: - | AA11: - | AB11: - | AC11: - | AD11: - | AE11: - | AF11: - | AG11: - | AH11: - | AI11: - | AJ11: - | AK11: - | AL11: =COUNTIF(G11:AK11,"근무") -> 0 | AM11: =COUNTIF(G11:AK11,"휴무") -> 0 | AN11: =COUNTIF(G11:AK11,"월차")+COUNTIF(G11:AK11,"반차") -> 0 | AO11: =COUNTIF(G11:AK11,"무단결근") -> 0 | AP11: =COUNTIF(G11:AK11,"무단조퇴") -> 0 | AQ11: =COUNTIF(G11:AK11,"권장휴무") -> 0 | AR11: =COUNTIF(G11:AK11,"권장조퇴") -> 0 | AS11: ='2-1.직원현황'!H10 -> 0 | AU11: ='2-1.직원현황'!J10 -> 0 | AV11: ='2-1.직원현황'!K10 -> 0 | AW11: ='2-1.직원현황'!L10 -> 0 | AY11: =IFERROR(VLOOKUP(B11,'2-1.직원현황'!$C$5:$AA$14,25,0),0) -> 0 | AZ11: =AY11/$AZ$4 -> 0
B12: ='2-1.직원현황'!C11 -> 0 | C12: ='2-1.직원현황'!D11 -> 선택 | D12: ='2-1.직원현황'!E11 -> 0 | E12: ='2-1.직원현황'!F11 -> 0 | F12: ='2-1.직원현황'!G11 -> 0 | G12: - | H12: - | I12: - | J12: - | K12: - | L12: - | M12: - | N12: - | O12: - | P12: - | Q12: - | R12: - | S12: - | T12: - | U12: - | V12: - | W12: - | X12: - | Y12: - | Z12: - | AA12: - | AB12: - | AC12: - | AD12: - | AE12: - | AF12: - | AG12: - | AH12: - | AI12: - | AJ12: - | AK12: - | AL12: =COUNTIF(G12:AK12,"근무") -> 0 | AM12: =COUNTIF(G12:AK12,"휴무") -> 0 | AN12: =COUNTIF(G12:AK12,"월차")+COUNTIF(G12:AK12,"반차") -> 0 | AO12: =COUNTIF(G12:AK12,"무단결근") -> 0 | AP12: =COUNTIF(G12:AK12,"무단조퇴") -> 0 | AQ12: =COUNTIF(G12:AK12,"권장휴무") -> 0 | AR12: =COUNTIF(G12:AK12,"권장조퇴") -> 0 | AS12: ='2-1.직원현황'!H11 -> 0 | AU12: ='2-1.직원현황'!J11 -> 0 | AV12: ='2-1.직원현황'!K11 -> 0 | AW12: ='2-1.직원현황'!L11 -> 0 | AY12: =IFERROR(VLOOKUP(B12,'2-1.직원현황'!$C$5:$AA$14,25,0),0) -> 0 | AZ12: =AY12/$AZ$4 -> 0
B13: ='2-1.직원현황'!C12 -> 0 | C13: ='2-1.직원현황'!D12 -> 선택 | D13: ='2-1.직원현황'!E12 -> 0 | E13: ='2-1.직원현황'!F12 -> 0 | F13: ='2-1.직원현황'!G12 -> 0 | G13: - | H13: - | I13: - | J13: - | K13: - | L13: - | M13: - | N13: - | O13: - | P13: - | Q13: - | R13: - | S13: - | T13: - | U13: - | V13: - | W13: - | X13: - | Y13: - | Z13: - | AA13: - | AB13: - | AC13: - | AD13: - | AE13: - | AF13: - | AG13: - | AH13: - | AI13: - | AJ13: - | AK13: - | AL13: =COUNTIF(G13:AK13,"근무") -> 0 | AM13: =COUNTIF(G13:AK13,"휴무") -> 0 | AN13: =COUNTIF(G13:AK13,"월차")+COUNTIF(G13:AK13,"반차") -> 0 | AO13: =COUNTIF(G13:AK13,"무단결근") -> 0 | AP13: =COUNTIF(G13:AK13,"무단조퇴") -> 0 | AQ13: =COUNTIF(G13:AK13,"권장휴무") -> 0 | AR13: =COUNTIF(G13:AK13,"권장조퇴") -> 0 | AS13: ='2-1.직원현황'!H12 -> 0 | AU13: ='2-1.직원현황'!J12 -> 0 | AV13: ='2-1.직원현황'!K12 -> 0 | AW13: ='2-1.직원현황'!L12 -> 0 | AY13: =IFERROR(VLOOKUP(B13,'2-1.직원현황'!$C$5:$AA$14,25,0),0) -> 0 | AZ13: =AY13/$AZ$4 -> 0
B14: ='2-1.직원현황'!C13 -> 0 | C14: ='2-1.직원현황'!D13 -> 선택 | D14: ='2-1.직원현황'!E13 -> 0 | E14: ='2-1.직원현황'!F13 -> 0 | F14: ='2-1.직원현황'!G13 -> 0 | G14: - | H14: - | I14: - | J14: - | K14: - | L14: - | M14: - | N14: - | O14: - | P14: - | Q14: - | R14: - | S14: - | T14: - | U14: - | V14: - | W14: - | X14: - | Y14: - | Z14: - | AA14: - | AB14: - | AC14: - | AD14: - | AE14: - | AF14: - | AG14: - | AH14: - | AI14: - | AJ14: - | AK14: - | AL14: =COUNTIF(G14:AK14,"근무") -> 0 | AM14: =COUNTIF(G14:AK14,"휴무") -> 0 | AN14: =COUNTIF(G14:AK14,"월차")+COUNTIF(G14:AK14,"반차") -> 0 | AO14: =COUNTIF(G14:AK14,"무단결근") -> 0 | AP14: =COUNTIF(G14:AK14,"무단조퇴") -> 0 | AQ14: =COUNTIF(G14:AK14,"권장휴무") -> 0 | AR14: =COUNTIF(G14:AK14,"권장조퇴") -> 0 | AS14: ='2-1.직원현황'!H13 -> 0 | AU14: ='2-1.직원현황'!J13 -> 0 | AV14: ='2-1.직원현황'!K13 -> 0 | AW14: ='2-1.직원현황'!L13 -> 0 | AY14: =IFERROR(VLOOKUP(B14,'2-1.직원현황'!$C$5:$AA$14,25,0),0) -> 0 | AZ14: =AY14/$AZ$4 -> 0
B15: ='2-1.직원현황'!C14 -> 0 | C15: ='2-1.직원현황'!D14 -> 선택 | D15: ='2-1.직원현황'!E14 -> 0 | E15: ='2-1.직원현황'!F14 -> 0 | F15: ='2-1.직원현황'!G14 -> 0 | G15: - | H15: - | I15: - | J15: - | K15: - | L15: - | M15: - | N15: - | O15: - | P15: - | Q15: - | R15: - | S15: - | T15: - | U15: - | V15: - | W15: - | X15: - | Y15: - | Z15: - | AA15: - | AB15: - | AC15: - | AD15: - | AE15: - | AF15: - | AG15: - | AH15: - | AI15: - | AJ15: - | AK15: - | AL15: =COUNTIF(G15:AK15,"근무") -> 0 | AM15: =COUNTIF(G15:AK15,"휴무") -> 0 | AN15: =COUNTIF(G15:AK15,"월차")+COUNTIF(G15:AK15,"반차") -> 0 | AO15: =COUNTIF(G15:AK15,"무단결근") -> 0 | AP15: =COUNTIF(G15:AK15,"무단조퇴") -> 0 | AQ15: =COUNTIF(G15:AK15,"권장휴무") -> 0 | AR15: =COUNTIF(G15:AK15,"권장조퇴") -> 0 | AS15: ='2-1.직원현황'!H14 -> 0 | AU15: ='2-1.직원현황'!J14 -> 0 | AV15: ='2-1.직원현황'!K14 -> 0 | AW15: ='2-1.직원현황'!L14 -> 0 | AY15: =IFERROR(VLOOKUP(B15,'2-1.직원현황'!$C$5:$AA$14,25,0),0) -> 0 | AZ15: =AY15/$AZ$4 -> 0
B16: ='2-1.직원현황'!C18 -> 김지용 | C16: ='2-1.직원현황'!D18 -> 선택 | D16: ='2-1.직원현황'!E18 -> 0 | E16: ='2-1.직원현황'!F18 -> 46113 | F16: ='2-1.직원현황'!G18 -> 0 | G16: 근무 | H16: 근무 | I16: 근무 | J16: 근무 | K16: 근무 | L16: 휴무 | M16: 근무 | N16: 근무 | O16: 근무 | P16: 근무 | Q16: 근무 | R16: 근무 | S16: 휴무 | T16: 휴무 | U16: 근무 | V16: 근무 | W16: 근무 | X16: 근무 | Y16: 근무 | Z16: 휴무 | AA16: 근무 | AB16: 근무 | AC16: 휴무 | AD16: 근무 | AE16: 근무 | AF16: 근무 | AG16: - | AH16: - | AI16: - | AJ16: - | AK16: - | AL16: =COUNTIF(G16:AK16,"근무") -> 21 | AM16: =COUNTIF(G16:AK16,"휴무") -> 5 | AN16: =COUNTIF(G16:AK16,"월차")+COUNTIF(G16:AK16,"반차") -> 0 | AO16: =COUNTIF(G16:AK16,"무단결근") -> 0 | AP16: =COUNTIF(G16:AK16,"무단조퇴") -> 0 | AQ16: =COUNTIF(G16:AK16,"권장휴무") -> 0 | AR16: =COUNTIF(G16:AK16,"권장조퇴") -> 0 | AS16: ='2-1.직원현황'!H18 -> 0 | AU16: ='2-1.직원현황'!J18 -> 0 | AV16: ='2-1.직원현황'!K18 -> 0 | AW16: ='2-1.직원현황'!L18 -> 신한 110 431 372066 | AY16: =IFERROR(VLOOKUP(B16,'2-1.직원현황'!$C$18:$AA$27,25,0),0) -> 4000000 | AZ16: =AY16/$AZ$4 -> 133333.33
B17: ='2-1.직원현황'!C19 -> 이도형 | C17: ='2-1.직원현황'!D19 -> 선택 | D17: ='2-1.직원현황'!E19 -> 0 | E17: ='2-1.직원현황'!F19 -> 46125 | F17: ='2-1.직원현황'!G19 -> 0 | G17: - | H17: - | I17: - | J17: - | K17: - | L17: - | M17: - | N17: - | O17: - | P17: - | Q17: - | R17: - | S17: 근무 | T17: 근무 | U17: 근무 | V17: 근무 | W17: 근무 | X17: 근무 | Y17: 휴무 | Z17: 근무 | AA17: 근무 | AB17: 근무 | AC17: 근무 | AD17: 근무 | AE17: 근무 | AF17: 근무 | AG17: - | AH17: - | AI17: - | AJ17: - | AK17: - | AL17: =COUNTIF(G17:AK17,"근무") -> 13 | AM17: =COUNTIF(G17:AK17,"휴무") -> 1 | AN17: =COUNTIF(G17:AK17,"월차")+COUNTIF(G17:AK17,"반차") -> 0 | AO17: =COUNTIF(G17:AK17,"무단결근") -> 0 | AP17: =COUNTIF(G17:AK17,"무단조퇴") -> 0 | AQ17: =COUNTIF(G17:AK17,"권장휴무") -> 0 | AR17: =COUNTIF(G17:AK17,"권장조퇴") -> 0 | AS17: ='2-1.직원현황'!H19 -> 0 | AU17: ='2-1.직원현황'!J19 -> 0 | AV17: ='2-1.직원현황'!K19 -> 0 | AW17: ='2-1.직원현황'!L19 -> 0 | AY17: =IFERROR(VLOOKUP(B17,'2-1.직원현황'!$C$18:$AA$27,25,0),0) -> 3400000 | AZ17: =AY17/$AZ$4 -> 113333.33
B18: ='2-1.직원현황'!C20 -> 0 | C18: ='2-1.직원현황'!D20 -> 선택 | D18: ='2-1.직원현황'!E20 -> 0 | E18: ='2-1.직원현황'!F20 -> 0 | F18: ='2-1.직원현황'!G20 -> 0 | G18: - | H18: - | I18: - | J18: - | K18: - | L18: - | M18: - | N18: - | O18: - | P18: - | Q18: - | R18: - | S18: - | T18: - | U18: - | V18: - | W18: - | X18: - | Y18: - | Z18: - | AA18: - | AB18: - | AC18: - | AD18: - | AE18: - | AF18: - | AG18: - | AH18: - | AI18: - | AJ18: - | AK18: - | AL18: =COUNTIF(G18:AK18,"근무") -> 0 | AM18: =COUNTIF(G18:AK18,"휴무") -> 0 | AN18: =COUNTIF(G18:AK18,"월차")+COUNTIF(G18:AK18,"반차") -> 0 | AO18: =COUNTIF(G18:AK18,"무단결근") -> 0 | AP18: =COUNTIF(G18:AK18,"무단조퇴") -> 0 | AQ18: =COUNTIF(G18:AK18,"권장휴무") -> 0 | AR18: =COUNTIF(G18:AK18,"권장조퇴") -> 0 | AS18: ='2-1.직원현황'!H20 -> 0 | AU18: ='2-1.직원현황'!J20 -> 0 | AV18: ='2-1.직원현황'!K20 -> 0 | AW18: ='2-1.직원현황'!L20 -> 0 | AY18: =IFERROR(VLOOKUP(B18,'2-1.직원현황'!$C$18:$AA$27,25,0),0) -> 0 | AZ18: =AY18/$AZ$4 -> 0
B19: ='2-1.직원현황'!C21 -> 0 | C19: ='2-1.직원현황'!D21 -> 선택 | D19: ='2-1.직원현황'!E21 -> 0 | E19: ='2-1.직원현황'!F21 -> 0 | F19: ='2-1.직원현황'!G21 -> 0 | G19: - | H19: - | I19: - | J19: - | K19: - | L19: - | M19: - | N19: - | O19: - | P19: - | Q19: - | R19: - | S19: - | T19: - | U19: - | V19: - | W19: - | X19: - | Y19: - | Z19: - | AA19: - | AB19: - | AC19: - | AD19: - | AE19: - | AF19: - | AG19: - | AH19: - | AI19: - | AJ19: - | AK19: - | AL19: =COUNTIF(G19:AK19,"근무") -> 0 | AM19: =COUNTIF(G19:AK19,"휴무") -> 0 | AN19: =COUNTIF(G19:AK19,"월차")+COUNTIF(G19:AK19,"반차") -> 0 | AO19: =COUNTIF(G19:AK19,"무단결근") -> 0 | AP19: =COUNTIF(G19:AK19,"무단조퇴") -> 0 | AQ19: =COUNTIF(G19:AK19,"권장휴무") -> 0 | AR19: =COUNTIF(G19:AK19,"권장조퇴") -> 0 | AS19: ='2-1.직원현황'!H21 -> 0 | AU19: ='2-1.직원현황'!J21 -> 0 | AV19: ='2-1.직원현황'!K21 -> 0 | AW19: ='2-1.직원현황'!L21 -> 0 | AY19: =IFERROR(VLOOKUP(B19,'2-1.직원현황'!$C$18:$AA$27,25,0),0) -> 0 | AZ19: =AY19/$AZ$4 -> 0
B20: ='2-1.직원현황'!C22 -> 0 | C20: ='2-1.직원현황'!D22 -> 선택 | D20: ='2-1.직원현황'!E22 -> 0 | E20: ='2-1.직원현황'!F22 -> 0 | F20: ='2-1.직원현황'!G22 -> 0 | G20: - | H20: - | I20: - | J20: - | K20: - | L20: - | M20: - | N20: - | O20: - | P20: - | Q20: - | R20: - | S20: - | T20: - | U20: - | V20: - | W20: - | X20: - | Y20: - | Z20: - | AA20: - | AB20: - | AC20: - | AD20: - | AE20: - | AF20: - | AG20: - | AH20: - | AI20: - | AJ20: - | AK20: - | AL20: =COUNTIF(G20:AK20,"근무") -> 0 | AM20: =COUNTIF(G20:AK20,"휴무") -> 0 | AN20: =COUNTIF(G20:AK20,"월차")+COUNTIF(G20:AK20,"반차") -> 0 | AO20: =COUNTIF(G20:AK20,"무단결근") -> 0 | AP20: =COUNTIF(G20:AK20,"무단조퇴") -> 0 | AQ20: =COUNTIF(G20:AK20,"권장휴무") -> 0 | AR20: =COUNTIF(G20:AK20,"권장조퇴") -> 0 | AS20: ='2-1.직원현황'!H22 -> 0 | AU20: ='2-1.직원현황'!J22 -> 0 | AV20: ='2-1.직원현황'!K22 -> 0 | AW20: ='2-1.직원현황'!L22 -> 0 | AY20: =IFERROR(VLOOKUP(B20,'2-1.직원현황'!$C$18:$AA$27,25,0),0) -> 0 | AZ20: =AY20/$AZ$4 -> 0
B21: ='2-1.직원현황'!C23 -> 0 | C21: ='2-1.직원현황'!D23 -> 선택 | D21: ='2-1.직원현황'!E23 -> 0 | E21: ='2-1.직원현황'!F23 -> 0 | F21: ='2-1.직원현황'!G23 -> 0 | G21: - | H21: - | I21: - | J21: - | K21: - | L21: - | M21: - | N21: - | O21: - | P21: - | Q21: - | R21: - | S21: - | T21: - | U21: - | V21: - | W21: - | X21: - | Y21: - | Z21: - | AA21: - | AB21: - | AC21: - | AD21: - | AE21: - | AF21: - | AG21: - | AH21: - | AI21: - | AJ21: - | AK21: - | AL21: =COUNTIF(G21:AK21,"근무") -> 0 | AM21: =COUNTIF(G21:AK21,"휴무") -> 0 | AN21: =COUNTIF(G21:AK21,"월차")+COUNTIF(G21:AK21,"반차") -> 0 | AO21: =COUNTIF(G21:AK21,"무단결근") -> 0 | AP21: =COUNTIF(G21:AK21,"무단조퇴") -> 0 | AQ21: =COUNTIF(G21:AK21,"권장휴무") -> 0 | AR21: =COUNTIF(G21:AK21,"권장조퇴") -> 0 | AS21: ='2-1.직원현황'!H23 -> 0 | AU21: ='2-1.직원현황'!J23 -> 0 | AV21: ='2-1.직원현황'!K23 -> 0 | AW21: ='2-1.직원현황'!L23 -> 0 | AY21: =IFERROR(VLOOKUP(B21,'2-1.직원현황'!$C$18:$AA$27,25,0),0) -> 0 | AZ21: =AY21/$AZ$4 -> 0
B22: ='2-1.직원현황'!C24 -> 0 | C22: ='2-1.직원현황'!D24 -> 선택 | D22: ='2-1.직원현황'!E24 -> 0 | E22: ='2-1.직원현황'!F24 -> 0 | F22: ='2-1.직원현황'!G24 -> 0 | G22: - | H22: - | I22: - | J22: - | K22: - | L22: - | M22: - | N22: - | O22: - | P22: - | Q22: - | R22: - | S22: - | T22: - | U22: - | V22: - | W22: - | X22: - | Y22: - | Z22: - | AA22: - | AB22: - | AC22: - | AD22: - | AE22: - | AF22: - | AG22: - | AH22: - | AI22: - | AJ22: - | AK22: - | AL22: =COUNTIF(G22:AK22,"근무") -> 0 | AM22: =COUNTIF(G22:AK22,"휴무") -> 0 | AN22: =COUNTIF(G22:AK22,"월차")+COUNTIF(G22:AK22,"반차") -> 0 | AO22: =COUNTIF(G22:AK22,"무단결근") -> 0 | AP22: =COUNTIF(G22:AK22,"무단조퇴") -> 0 | AQ22: =COUNTIF(G22:AK22,"권장휴무") -> 0 | AR22: =COUNTIF(G22:AK22,"권장조퇴") -> 0 | AS22: ='2-1.직원현황'!H24 -> 0 | AU22: ='2-1.직원현황'!J24 -> 0 | AV22: ='2-1.직원현황'!K24 -> 0 | AW22: ='2-1.직원현황'!L24 -> 0 | AY22: =IFERROR(VLOOKUP(B22,'2-1.직원현황'!$C$18:$AA$27,25,0),0) -> 0 | AZ22: =AY22/$AZ$4 -> 0
B23: ='2-1.직원현황'!C25 -> 0 | C23: ='2-1.직원현황'!D25 -> 선택 | D23: ='2-1.직원현황'!E25 -> 0 | E23: ='2-1.직원현황'!F25 -> 0 | F23: ='2-1.직원현황'!G25 -> 0 | G23: - | H23: - | I23: - | J23: - | K23: - | L23: - | M23: - | N23: - | O23: - | P23: - | Q23: - | R23: - | S23: - | T23: - | U23: - | V23: - | W23: - | X23: - | Y23: - | Z23: - | AA23: - | AB23: - | AC23: - | AD23: - | AE23: - | AF23: - | AG23: - | AH23: - | AI23: - | AJ23: - | AK23: - | AL23: =COUNTIF(G23:AK23,"근무") -> 0 | AM23: =COUNTIF(G23:AK23,"휴무") -> 0 | AN23: =COUNTIF(G23:AK23,"월차")+COUNTIF(G23:AK23,"반차") -> 0 | AO23: =COUNTIF(G23:AK23,"무단결근") -> 0 | AP23: =COUNTIF(G23:AK23,"무단조퇴") -> 0 | AQ23: =COUNTIF(G23:AK23,"권장휴무") -> 0 | AR23: =COUNTIF(G23:AK23,"권장조퇴") -> 0 | AS23: ='2-1.직원현황'!H25 -> 0 | AU23: ='2-1.직원현황'!J25 -> 0 | AV23: ='2-1.직원현황'!K25 -> 0 | AW23: ='2-1.직원현황'!L25 -> 0 | AY23: =IFERROR(VLOOKUP(B23,'2-1.직원현황'!$C$18:$AA$27,25,0),0) -> 0 | AZ23: =AY23/$AZ$4 -> 0
B24: ='2-1.직원현황'!C26 -> 0 | C24: ='2-1.직원현황'!D26 -> 선택 | D24: ='2-1.직원현황'!E26 -> 0 | E24: ='2-1.직원현황'!F26 -> 0 | F24: ='2-1.직원현황'!G26 -> 0 | G24: - | H24: - | I24: - | J24: - | K24: - | L24: - | M24: - | N24: - | O24: - | P24: - | Q24: - | R24: - | S24: - | T24: - | U24: - | V24: - | W24: - | X24: - | Y24: - | Z24: - | AA24: - | AB24: - | AC24: - | AD24: - | AE24: - | AF24: - | AG24: - | AH24: - | AI24: - | AJ24: - | AK24: - | AL24: =COUNTIF(G24:AK24,"근무") -> 0 | AM24: =COUNTIF(G24:AK24,"휴무") -> 0 | AN24: =COUNTIF(G24:AK24,"월차")+COUNTIF(G24:AK24,"반차") -> 0 | AO24: =COUNTIF(G24:AK24,"무단결근") -> 0 | AP24: =COUNTIF(G24:AK24,"무단조퇴") -> 0 | AQ24: =COUNTIF(G24:AK24,"권장휴무") -> 0 | AR24: =COUNTIF(G24:AK24,"권장조퇴") -> 0 | AS24: ='2-1.직원현황'!H26 -> 0 | AU24: ='2-1.직원현황'!J26 -> 0 | AV24: ='2-1.직원현황'!K26 -> 0 | AW24: ='2-1.직원현황'!L26 -> 0 | AY24: =IFERROR(VLOOKUP(B24,'2-1.직원현황'!$C$18:$AA$27,25,0),0) -> 0 | AZ24: =AY24/$AZ$4 -> 0
B25: ='2-1.직원현황'!C27 -> 0 | C25: ='2-1.직원현황'!D27 -> 선택 | D25: ='2-1.직원현황'!E27 -> 0 | E25: ='2-1.직원현황'!F27 -> 0 | F25: ='2-1.직원현황'!G27 -> 0 | G25: - | H25: - | I25: - | J25: - | K25: - | L25: - | M25: - | N25: - | O25: - | P25: - | Q25: - | R25: - | S25: - | T25: - | U25: - | V25: - | W25: - | X25: - | Y25: - | Z25: - | AA25: - | AB25: - | AC25: - | AD25: - | AE25: - | AF25: - | AG25: - | AH25: - | AI25: - | AJ25: - | AK25: - | AL25: =COUNTIF(G25:AK25,"근무") -> 0 | AM25: =COUNTIF(G25:AK25,"휴무") -> 0 | AN25: =COUNTIF(G25:AK25,"월차")+COUNTIF(G25:AK25,"반차") -> 0 | AO25: =COUNTIF(G25:AK25,"무단결근") -> 0 | AP25: =COUNTIF(G25:AK25,"무단조퇴") -> 0 | AQ25: =COUNTIF(G25:AK25,"권장휴무") -> 0 | AR25: =COUNTIF(G25:AK25,"권장조퇴") -> 0 | AS25: ='2-1.직원현황'!H27 -> 0 | AU25: ='2-1.직원현황'!J27 -> 0 | AV25: ='2-1.직원현황'!K27 -> 0 | AW25: ='2-1.직원현황'!L27 -> 0 | AY25: =IFERROR(VLOOKUP(B25,'2-1.직원현황'!$C$18:$AA$27,25,0),0) -> 0 | AZ25: =AY25/$AZ$4 -> 0
B26: 총 근로자 | G26: =COUNTIF(G6:G25,"근무")+COUNTIF(G6:G25,"지원") -> 2 | H26: =COUNTIF(H6:H25,"근무")+COUNTIF(H6:H25,"지원") -> 4 | I26: =COUNTIF(I6:I25,"근무")+COUNTIF(I6:I25,"지원") -> 4 | J26: =COUNTIF(J6:J25,"근무")+COUNTIF(J6:J25,"지원") -> 4 | K26: =COUNTIF(K6:K25,"근무")+COUNTIF(K6:K25,"지원") -> 3 | L26: =COUNTIF(L6:L25,"근무")+COUNTIF(L6:L25,"지원") -> 2 | M26: =COUNTIF(M6:M25,"근무")+COUNTIF(M6:M25,"지원") -> 4 | N26: =COUNTIF(N6:N25,"근무")+COUNTIF(N6:N25,"지원") -> 3 | ... AK26: =COUNTIF(AK6:AK25,"근무")+COUNTIF(AK6:AK25,"지원") -> 0
B28: ② 알바 근무현황 _ 근무시간 직접 작성(예 : 1, 1.5, 2, 2.5…)
B29: 이름 | C29: 파트 (홀/주방) | D29: 직책 | E29: 입사일 | F29: 퇴사일 (마지막근무일) | G29: 1 | H29: 2 | I29: 3 | J29: 4 | K29: 5 | L29: 6 | M29: 7 | N29: 8 | O29: 9 | P29: 10 | Q29: 11 | R29: 12 | S29: 13 | T29: 14 | U29: 15 | V29: 16 | W29: 17 | X29: 18 | Y29: 19 | Z29: 20 | AA29: 21 | AB29: 22 | AC29: 23 | AD29: 24 | AE29: 25 | AF29: 26 | AG29: 27 | AH29: 28 | AI29: 29 | AJ29: 30 | AK29: 31 | AL29: 총근무시간 | AM29: 시급 | AN29: 월급여 | AU29: 연락처 | AV29: 주민번호 | AW29: 급여계좌
B31: ='2-1.직원현황'!C31 -> 최은태 | C31: ='2-1.직원현황'!D31 -> 주방 | D31: ='2-1.직원현황'!E31 -> 파트타임 | E31: ='2-1.직원현황'!F31 -> 0 | F31: ='2-1.직원현황'!G31 -> 0 | G31: 10 | H31: 10 | I31: 10 | J31: 10 | K31: 10 | L31: 10 | N31: 10 | O31: 10 | P31: 10 | Q31: 10 | R31: 10 | S31: 10 | T31: 10 | U31: 10 | V31: 10 | W31: 10 | X31: 10 | Y31: 10 | Z31: 10 | AB31: 10 | AC31: 10 | AD31: 10 | AE31: 10 | AF31: 10 | AL31: =SUM(G31:AK31) -> 240 | AM31: ='2-1.직원현황'!I31 -> 20000 | AN31: =AL31*AM31 -> 4800000 | AU31: ='2-1.직원현황'!J31 -> 0 | AV31: ='2-1.직원현황'!K31 -> 800303-2637310 | AW31: ='2-1.직원현황'!L31 -> 경남 221 0110 1350 07
B32: ='2-1.직원현황'!C32 -> 이서문 | C32: ='2-1.직원현황'!D32 -> 선택 | D32: ='2-1.직원현황'!E32 -> 파트타임 | E32: ='2-1.직원현황'!F32 -> 0 | F32: ='2-1.직원현황'!G32 -> 0 | I32: 6 | J32: 8 | P32: 6 | Q32: 7 | W32: 7 | X32: 8 | AD32: 7 | AE32: 9 | AF32: 10 | AL32: =SUM(G32:AK32) -> 68 | AM32: ='2-1.직원현황'!I32 -> 13000 | AN32: =AL32*AM32 -> 884000 | AU32: ='2-1.직원현황'!J32 -> 0 | AV32: ='2-1.직원현황'!K32 -> 960527-2471215 | AW32: ='2-1.직원현황'!L32 -> 카카오 3333 344 538401
B33: ='2-1.직원현황'!C33 -> 김복순 | C33: ='2-1.직원현황'!D33 -> 선택 | D33: ='2-1.직원현황'!E33 -> 파트타임 | E33: ='2-1.직원현황'!F33 -> 0 | F33: ='2-1.직원현황'!G33 -> 0 | I33: 6 | J33: 6.5 | P33: 6 | Q33: 6 | AL33: =SUM(G33:AK33) -> 24.5 | AM33: ='2-1.직원현황'!I33 -> 12000 | AN33: =AL33*AM33 -> 294000 | AU33: ='2-1.직원현황'!J33 -> 0 | AV33: ='2-1.직원현황'!K33 -> 601109-6102493 | AW33: ='2-1.직원현황'!L33 -> 국민 424002 01 337949
B34: ='2-1.직원현황'!C34 -> 이도형 | C34: ='2-1.직원현황'!D34 -> 선택 | D34: ='2-1.직원현황'!E34 -> 파트타임 | E34: ='2-1.직원현황'!F34 -> 0 | F34: ='2-1.직원현황'!G34 -> 0 | O34: 7 | P34: 7 | AL34: =SUM(G34:AK34) -> 14 | AM34: ='2-1.직원현황'!I34 -> 13000 | AN34: =AL34*AM34 -> 182000 | AU34: ='2-1.직원현황'!J34 -> 0 | AV34: ='2-1.직원현황'!K34 -> 0 | AW34: ='2-1.직원현황'!L34 -> 0
B35: ='2-1.직원현황'!C35 -> 송은비 | C35: ='2-1.직원현황'!D35 -> 선택 | D35: ='2-1.직원현황'!E35 -> 파트타임 | E35: ='2-1.직원현황'!F35 -> 0 | F35: ='2-1.직원현황'!G35 -> 0 | AE35: 7 | AL35: =SUM(G35:AK35) -> 7 | AM35: ='2-1.직원현황'!I35 -> 13000 | AN35: =AL35*AM35 -> 91000 | AU35: ='2-1.직원현황'!J35 -> 0 | AV35: ='2-1.직원현황'!K35 -> 0 | AW35: ='2-1.직원현황'!L35 -> 0
B36: ='2-1.직원현황'!C36 -> 김범창 | C36: ='2-1.직원현황'!D36 -> 선택 | D36: ='2-1.직원현황'!E36 -> 파트타임 | E36: ='2-1.직원현황'!F36 -> 0 | F36: ='2-1.직원현황'!G36 -> 0 | AE36: 3.5 | AL36: =SUM(G36:AK36) -> 3.5 | AM36: ='2-1.직원현황'!I36 -> 13000 | AN36: =AL36*AM36 -> 45500 | AU36: ='2-1.직원현황'!J36 -> 0 | AV36: ='2-1.직원현황'!K36 -> 0 | AW36: ='2-1.직원현황'!L36 -> 0
B37: ='2-1.직원현황'!C37 -> 0 | C37: ='2-1.직원현황'!D37 -> 선택 | D37: ='2-1.직원현황'!E37 -> 파트타임 | E37: ='2-1.직원현황'!F37 -> 0 | F37: ='2-1.직원현황'!G37 -> 0 | AL37: =SUM(G37:AK37) -> 0 | AM37: ='2-1.직원현황'!I37 -> 0 | AN37: =AL37*AM37 -> 0 | AU37: ='2-1.직원현황'!J37 -> 0 | AV37: ='2-1.직원현황'!K37 -> 0 | AW37: ='2-1.직원현황'!L37 -> 0
B38: ='2-1.직원현황'!C38 -> 0 | C38: ='2-1.직원현황'!D38 -> 선택 | D38: ='2-1.직원현황'!E38 -> 파트타임 | E38: ='2-1.직원현황'!F38 -> 0 | F38: ='2-1.직원현황'!G38 -> 0 | AL38: =SUM(G38:AK38) -> 0 | AM38: ='2-1.직원현황'!I38 -> 0 | AN38: =AL38*AM38 -> 0 | AU38: ='2-1.직원현황'!J38 -> 0 | AV38: ='2-1.직원현황'!K38 -> 0 | AW38: ='2-1.직원현황'!L38 -> 0
B39: ='2-1.직원현황'!C39 -> 0 | C39: ='2-1.직원현황'!D39 -> 선택 | D39: ='2-1.직원현황'!E39 -> 파트타임 | E39: ='2-1.직원현황'!F39 -> 0 | F39: ='2-1.직원현황'!G39 -> 0 | AL39: =SUM(G39:AK39) -> 0 | AM39: ='2-1.직원현황'!I39 -> 0 | AN39: =AL39*AM39 -> 0 | AU39: ='2-1.직원현황'!J39 -> 0 | AV39: ='2-1.직원현황'!K39 -> 0 | AW39: ='2-1.직원현황'!L39 -> 0
B40: ='2-1.직원현황'!C40 -> 0 | C40: ='2-1.직원현황'!D40 -> 선택 | D40: ='2-1.직원현황'!E40 -> 파트타임 | E40: ='2-1.직원현황'!F40 -> 0 | F40: ='2-1.직원현황'!G40 -> 0 | AL40: =SUM(G40:AK40) -> 0 | AM40: ='2-1.직원현황'!I40 -> 0 | AN40: =AL40*AM40 -> 0 | AU40: ='2-1.직원현황'!J40 -> 0 | AV40: ='2-1.직원현황'!K40 -> 0 | AW40: ='2-1.직원현황'!L40 -> 0
B41: ='2-1.직원현황'!C41 -> 0 | C41: ='2-1.직원현황'!D41 -> 선택 | D41: ='2-1.직원현황'!E41 -> 파트타임 | E41: ='2-1.직원현황'!F41 -> 0 | F41: ='2-1.직원현황'!G41 -> 0 | AL41: =SUM(G41:AK41) -> 0 | AM41: ='2-1.직원현황'!I41 -> 0 | AN41: =AL41*AM41 -> 0 | AU41: ='2-1.직원현황'!J41 -> 0 | AV41: ='2-1.직원현황'!K41 -> 0 | AW41: ='2-1.직원현황'!L41 -> 0
B42: ='2-1.직원현황'!C42 -> 0 | C42: ='2-1.직원현황'!D42 -> 선택 | D42: ='2-1.직원현황'!E42 -> 파트타임 | E42: ='2-1.직원현황'!F42 -> 0 | F42: ='2-1.직원현황'!G42 -> 0 | AL42: =SUM(G42:AK42) -> 0 | AM42: ='2-1.직원현황'!I42 -> 0 | AN42: =AL42*AM42 -> 0 | AU42: ='2-1.직원현황'!J42 -> 0 | AV42: ='2-1.직원현황'!K42 -> 0 | AW42: ='2-1.직원현황'!L42 -> 0
B43: ='2-1.직원현황'!C43 -> 0 | C43: ='2-1.직원현황'!D43 -> 선택 | D43: ='2-1.직원현황'!E43 -> 파트타임 | E43: ='2-1.직원현황'!F43 -> 0 | F43: ='2-1.직원현황'!G43 -> 0 | AL43: =SUM(G43:AK43) -> 0 | AM43: ='2-1.직원현황'!I43 -> 0 | AN43: =AL43*AM43 -> 0 | AU43: ='2-1.직원현황'!J43 -> 0 | AV43: ='2-1.직원현황'!K43 -> 0 | AW43: ='2-1.직원현황'!L43 -> 0
...

Sheet 2-3.근무시간
A1: ■ 근무스케쥴표 | E1: ='0.기초및고정비'!C4&'0.기초및고정비'!D4 -> 2026년4월
A3: <작성방법>
B4: ←표시된 부분만 작성!! | E4: ① 정직원 스케쥴현황
A5: · 기록방법 (중요!!) | E5: 이름 | F5: 파트 (홀/주방) | G5: 직급 | H5: 1 | K5: 2 | N5: 3 | Q5: 4 | T5: 5 | W5: 6 | Z5: 7 | AC5: 8 | AF5: 9 | AI5: 10 | AL5: 11 | AO5: 12 | AR5: 13 | AU5: 14 | AX5: 15 | BA5: 16 | BD5: 17 | BG5: 18 | BJ5: 19 | BM5: 20 | BP5: 21 | BS5: 22 | BV5: 23 | BY5: 24 | CB5: 25 | CE5: 26 | CH5: 27 | CK5: 28 | CN5: 29 | CQ5: 30 | CT5: 31
H6: 출근 | I6: 퇴근 | J6: 근무시간 | K6: 출근 | L6: 퇴근 | M6: 근무시간 | N6: 출근 | O6: 퇴근 | P6: 근무시간 | Q6: 출근 | R6: 퇴근 | S6: 근무시간 | T6: 출근 | U6: 퇴근 | V6: 근무시간 | W6: 출근 | X6: 퇴근 | Y6: 근무시간 | Z6: 출근 | AA6: 퇴근 | AB6: 근무시간 | AC6: 출근 | AD6: 퇴근 | AE6: 근무시간 | AF6: 출근 | AG6: 퇴근 | AH6: 근무시간 | AI6: 출근 | AJ6: 퇴근 | AK6: 근무시간 | AL6: 출근 | AM6: 퇴근 | AN6: 근무시간 | AO6: 출근 | AP6: 퇴근 | AQ6: 근무시간 | AR6: 출근 | AS6: 퇴근 | AT6: 근무시간 | AU6: 출근 | AV6: 퇴근 | AW6: 근무시간 | AX6: 출근 | AY6: 퇴근 | AZ6: 근무시간 | BA6: 출근 | BB6: 퇴근 | BC6: 근무시간 | BD6: 출근 | BE6: 퇴근 | BF6: 근무시간 | BG6: 출근 | BH6: 퇴근 | BI6: 근무시간 | BJ6: 출근 | BK6: 퇴근 | BL6: 근무시간 | BM6: 출근 | BN6: 퇴근 | BO6: 근무시간 | BP6: 출근 | BQ6: 퇴근 | BR6: 근무시간 | BS6: 출근 | BT6: 퇴근 | BU6: 근무시간 | BV6: 출근 | BW6: 퇴근 | BX6: 근무시간 | BY6: 출근 | BZ6: 퇴근 | CA6: 근무시간 | CB6: 출근 | CC6: 퇴근 | CD6: 근무시간 | CE6: 출근 | CF6: 퇴근 | CG6: 근무시간 | CH6: 출근 | CI6: 퇴근 | CJ6: 근무시간 | CK6: 출근 | CL6: 퇴근 | CM6: 근무시간 | CN6: 출근 | CO6: 퇴근 | CP6: 근무시간 | CQ6: 출근 | CR6: 퇴근 | CS6: 근무시간 | CT6: 출근 | CU6: 퇴근 | CV6: 근무시간
A7: 구분 | C7: 기록방법 | E7: ='2-2.근무표'!B6 -> 박성배 | F7: ='2-2.근무표'!C6 -> 선택 | G7: ='2-2.근무표'!D6 -> 주방 | J7: =IFERROR(IF(((I7-H7+(I7<H7))*24)=0,"0",(I7-H7+(I7<H7))*24),"") -> 0 | M7: =IFERROR(IF(((L7-K7+(L7<K7))*24)=0,"0",(L7-K7+(L7<K7))*24),"") -> 0 | P7: =IFERROR(IF(((O7-N7+(O7<N7))*24)=0,"0",(O7-N7+(O7<N7))*24),"") -> 0 | S7: =IFERROR(IF(((R7-Q7+(R7<Q7))*24)=0,"0",(R7-Q7+(R7<Q7))*24),"") -> 0 | V7: =IFERROR(IF(((U7-T7+(U7<T7))*24)=0,"0",(U7-T7+(U7<T7))*24),"") -> 0 | Y7: =IFERROR(IF(((X7-W7+(X7<W7))*24)=0,"0",(X7-W7+(X7<W7))*24),"") -> 0 | AB7: =IFERROR(IF(((AA7-Z7+(AA7<Z7))*24)=0,"0",(AA7-Z7+(AA7<Z7))*24),"") -> 0 | AE7: =IFERROR(IF(((AD7-AC7+(AD7<AC7))*24)=0,"0",(AD7-AC7+(AD7<AC7))*24),"") -> 0 | AH7: =IFERROR(IF(((AG7-AF7+(AG7<AF7))*24)=0,"0",(AG7-AF7+(AG7<AF7))*24),"") -> 0 | AK7: =IFERROR(IF(((AJ7-AI7+(AJ7<AI7))*24)=0,"0",(AJ7-AI7+(AJ7<AI7))*24),"") -> 0 | AN7: =IFERROR(IF(((AM7-AL7+(AM7<AL7))*24)=0,"0",(AM7-AL7+(AM7<AL7))*24),"") -> 0 | AQ7: =IFERROR(IF(((AP7-AO7+(AP7<AO7))*24)=0,"0",(AP7-AO7+(AP7<AO7))*24),"") -> 0 | AT7: =IFERROR(IF(((AS7-AR7+(AS7<AR7))*24)=0,"0",(AS7-AR7+(AS7<AR7))*24),"") -> 0 | AW7: =IFERROR(IF(((AV7-AU7+(AV7<AU7))*24)=0,"0",(AV7-AU7+(AV7<AU7))*24),"") -> 0 | AZ7: =IFERROR(IF(((AY7-AX7+(AY7<AX7))*24)=0,"0",(AY7-AX7+(AY7<AX7))*24),"") -> 0 | BC7: =IFERROR(IF(((BB7-BA7+(BB7<BA7))*24)=0,"0",(BB7-BA7+(BB7<BA7))*24),"") -> 0 | BF7: =IFERROR(IF(((BE7-BD7+(BE7<BD7))*24)=0,"0",(BE7-BD7+(BE7<BD7))*24),"") -> 0 | BI7: =IFERROR(IF(((BH7-BG7+(BH7<BG7))*24)=0,"0",(BH7-BG7+(BH7<BG7))*24),"") -> 0 | BL7: =IFERROR(IF(((BK7-BJ7+(BK7<BJ7))*24)=0,"0",(BK7-BJ7+(BK7<BJ7))*24),"") -> 0 | BO7: =IFERROR(IF(((BN7-BM7+(BN7<BM7))*24)=0,"0",(BN7-BM7+(BN7<BM7))*24),"") -> 0 | BR7: =IFERROR(IF(((BQ7-BP7+(BQ7<BP7))*24)=0,"0",(BQ7-BP7+(BQ7<BP7))*24),"") -> 0 | BU7: =IFERROR(IF(((BT7-BS7+(BT7<BS7))*24)=0,"0",(BT7-BS7+(BT7<BS7))*24),"") -> 0 | BX7: =IFERROR(IF(((BW7-BV7+(BW7<BV7))*24)=0,"0",(BW7-BV7+(BW7<BV7))*24),"") -> 0 | CA7: =IFERROR(IF(((BZ7-BY7+(BZ7<BY7))*24)=0,"0",(BZ7-BY7+(BZ7<BY7))*24),"") -> 0 | CD7: =IFERROR(IF(((CC7-CB7+(CC7<CB7))*24)=0,"0",(CC7-CB7+(CC7<CB7))*24),"") -> 0 | CG7: =IFERROR(IF(((CF7-CE7+(CF7<CE7))*24)=0,"0",(CF7-CE7+(CF7<CE7))*24),"") -> 0 | CJ7: =IFERROR(IF(((CI7-CH7+(CI7<CH7))*24)=0,"0",(CI7-CH7+(CI7<CH7))*24),"") -> 0 | CM7: =IFERROR(IF(((CL7-CK7+(CL7<CK7))*24)=0,"0",(CL7-CK7+(CL7<CK7))*24),"") -> 0 | CP7: =IFERROR(IF(((CO7-CN7+(CO7<CN7))*24)=0,"0",(CO7-CN7+(CO7<CN7))*24),"") -> 0 | CS7: =IFERROR(IF(((CR7-CQ7+(CR7<CQ7))*24)=0,"0",(CR7-CQ7+(CR7<CQ7))*24),"") -> 0 | CV7: =IFERROR(IF(((CU7-CT7+(CU7<CT7))*24)=0,"0",(CU7-CT7+(CU7<CT7))*24),"") -> 0
A8: 출근시간 | C8: TT:MM | E8: ='2-2.근무표'!B7 -> 박참이 | F8: ='2-2.근무표'!C7 -> 선택 | G8: ='2-2.근무표'!D7 -> 주방 | J8: =IFERROR(IF(((I8-H8+(I8<H8))*24)=0,"0",(I8-H8+(I8<H8))*24),"") -> 0 | M8: =IFERROR(IF(((L8-K8+(L8<K8))*24)=0,"0",(L8-K8+(L8<K8))*24),"") -> 0 | P8: =IFERROR(IF(((O8-N8+(O8<N8))*24)=0,"0",(O8-N8+(O8<N8))*24),"") -> 0 | S8: =IFERROR(IF(((R8-Q8+(R8<Q8))*24)=0,"0",(R8-Q8+(R8<Q8))*24),"") -> 0 | V8: =IFERROR(IF(((U8-T8+(U8<T8))*24)=0,"0",(U8-T8+(U8<T8))*24),"") -> 0 | Y8: =IFERROR(IF(((X8-W8+(X8<W8))*24)=0,"0",(X8-W8+(X8<W8))*24),"") -> 0 | AB8: =IFERROR(IF(((AA8-Z8+(AA8<Z8))*24)=0,"0",(AA8-Z8+(AA8<Z8))*24),"") -> 0 | AE8: =IFERROR(IF(((AD8-AC8+(AD8<AC8))*24)=0,"0",(AD8-AC8+(AD8<AC8))*24),"") -> 0 | AH8: =IFERROR(IF(((AG8-AF8+(AG8<AF8))*24)=0,"0",(AG8-AF8+(AG8<AF8))*24),"") -> 0 | AK8: =IFERROR(IF(((AJ8-AI8+(AJ8<AI8))*24)=0,"0",(AJ8-AI8+(AJ8<AI8))*24),"") -> 0 | AN8: =IFERROR(IF(((AM8-AL8+(AM8<AL8))*24)=0,"0",(AM8-AL8+(AM8<AL8))*24),"") -> 0 | AQ8: =IFERROR(IF(((AP8-AO8+(AP8<AO8))*24)=0,"0",(AP8-AO8+(AP8<AO8))*24),"") -> 0 | AT8: =IFERROR(IF(((AS8-AR8+(AS8<AR8))*24)=0,"0",(AS8-AR8+(AS8<AR8))*24),"") -> 0 | AW8: =IFERROR(IF(((AV8-AU8+(AV8<AU8))*24)=0,"0",(AV8-AU8+(AV8<AU8))*24),"") -> 0 | AZ8: =IFERROR(IF(((AY8-AX8+(AY8<AX8))*24)=0,"0",(AY8-AX8+(AY8<AX8))*24),"") -> 0 | BC8: =IFERROR(IF(((BB8-BA8+(BB8<BA8))*24)=0,"0",(BB8-BA8+(BB8<BA8))*24),"") -> 0 | BF8: =IFERROR(IF(((BE8-BD8+(BE8<BD8))*24)=0,"0",(BE8-BD8+(BE8<BD8))*24),"") -> 0 | BI8: =IFERROR(IF(((BH8-BG8+(BH8<BG8))*24)=0,"0",(BH8-BG8+(BH8<BG8))*24),"") -> 0 | BL8: =IFERROR(IF(((BK8-BJ8+(BK8<BJ8))*24)=0,"0",(BK8-BJ8+(BK8<BJ8))*24),"") -> 0 | BO8: =IFERROR(IF(((BN8-BM8+(BN8<BM8))*24)=0,"0",(BN8-BM8+(BN8<BM8))*24),"") -> 0 | BR8: =IFERROR(IF(((BQ8-BP8+(BQ8<BP8))*24)=0,"0",(BQ8-BP8+(BQ8<BP8))*24),"") -> 0 | BU8: =IFERROR(IF(((BT8-BS8+(BT8<BS8))*24)=0,"0",(BT8-BS8+(BT8<BS8))*24),"") -> 0 | BX8: =IFERROR(IF(((BW8-BV8+(BW8<BV8))*24)=0,"0",(BW8-BV8+(BW8<BV8))*24),"") -> 0 | CA8: =IFERROR(IF(((BZ8-BY8+(BZ8<BY8))*24)=0,"0",(BZ8-BY8+(BZ8<BY8))*24),"") -> 0 | CD8: =IFERROR(IF(((CC8-CB8+(CC8<CB8))*24)=0,"0",(CC8-CB8+(CC8<CB8))*24),"") -> 0 | CG8: =IFERROR(IF(((CF8-CE8+(CF8<CE8))*24)=0,"0",(CF8-CE8+(CF8<CE8))*24),"") -> 0 | CJ8: =IFERROR(IF(((CI8-CH8+(CI8<CH8))*24)=0,"0",(CI8-CH8+(CI8<CH8))*24),"") -> 0 | CM8: =IFERROR(IF(((CL8-CK8+(CL8<CK8))*24)=0,"0",(CL8-CK8+(CL8<CK8))*24),"") -> 0 | CP8: =IFERROR(IF(((CO8-CN8+(CO8<CN8))*24)=0,"0",(CO8-CN8+(CO8<CN8))*24),"") -> 0 | CS8: =IFERROR(IF(((CR8-CQ8+(CR8<CQ8))*24)=0,"0",(CR8-CQ8+(CR8<CQ8))*24),"") -> 0 | CV8: =IFERROR(IF(((CU8-CT8+(CU8<CT8))*24)=0,"0",(CU8-CT8+(CU8<CT8))*24),"") -> 0
A9: 퇴근시간 | C9: TT:MM | E9: ='2-2.근무표'!B8 -> 이건호 | F9: ='2-2.근무표'!C8 -> 선택 | G9: ='2-2.근무표'!D8 -> 홀 | J9: =IFERROR(IF(((I9-H9+(I9<H9))*24)=0,"0",(I9-H9+(I9<H9))*24),"") -> 0 | M9: =IFERROR(IF(((L9-K9+(L9<K9))*24)=0,"0",(L9-K9+(L9<K9))*24),"") -> 0 | P9: =IFERROR(IF(((O9-N9+(O9<N9))*24)=0,"0",(O9-N9+(O9<N9))*24),"") -> 0 | S9: =IFERROR(IF(((R9-Q9+(R9<Q9))*24)=0,"0",(R9-Q9+(R9<Q9))*24),"") -> 0 | V9: =IFERROR(IF(((U9-T9+(U9<T9))*24)=0,"0",(U9-T9+(U9<T9))*24),"") -> 0 | Y9: =IFERROR(IF(((X9-W9+(X9<W9))*24)=0,"0",(X9-W9+(X9<W9))*24),"") -> 0 | AB9: =IFERROR(IF(((AA9-Z9+(AA9<Z9))*24)=0,"0",(AA9-Z9+(AA9<Z9))*24),"") -> 0 | AE9: =IFERROR(IF(((AD9-AC9+(AD9<AC9))*24)=0,"0",(AD9-AC9+(AD9<AC9))*24),"") -> 0 | AH9: =IFERROR(IF(((AG9-AF9+(AG9<AF9))*24)=0,"0",(AG9-AF9+(AG9<AF9))*24),"") -> 0 | AK9: =IFERROR(IF(((AJ9-AI9+(AJ9<AI9))*24)=0,"0",(AJ9-AI9+(AJ9<AI9))*24),"") -> 0 | AN9: =IFERROR(IF(((AM9-AL9+(AM9<AL9))*24)=0,"0",(AM9-AL9+(AM9<AL9))*24),"") -> 0 | AQ9: =IFERROR(IF(((AP9-AO9+(AP9<AO9))*24)=0,"0",(AP9-AO9+(AP9<AO9))*24),"") -> 0 | AT9: =IFERROR(IF(((AS9-AR9+(AS9<AR9))*24)=0,"0",(AS9-AR9+(AS9<AR9))*24),"") -> 0 | AW9: =IFERROR(IF(((AV9-AU9+(AV9<AU9))*24)=0,"0",(AV9-AU9+(AV9<AU9))*24),"") -> 0 | AZ9: =IFERROR(IF(((AY9-AX9+(AY9<AX9))*24)=0,"0",(AY9-AX9+(AY9<AX9))*24),"") -> 0 | BC9: =IFERROR(IF(((BB9-BA9+(BB9<BA9))*24)=0,"0",(BB9-BA9+(BB9<BA9))*24),"") -> 0 | BF9: =IFERROR(IF(((BE9-BD9+(BE9<BD9))*24)=0,"0",(BE9-BD9+(BE9<BD9))*24),"") -> 0 | BI9: =IFERROR(IF(((BH9-BG9+(BH9<BG9))*24)=0,"0",(BH9-BG9+(BH9<BG9))*24),"") -> 0 | BL9: =IFERROR(IF(((BK9-BJ9+(BK9<BJ9))*24)=0,"0",(BK9-BJ9+(BK9<BJ9))*24),"") -> 0 | BO9: =IFERROR(IF(((BN9-BM9+(BN9<BM9))*24)=0,"0",(BN9-BM9+(BN9<BM9))*24),"") -> 0 | BR9: =IFERROR(IF(((BQ9-BP9+(BQ9<BP9))*24)=0,"0",(BQ9-BP9+(BQ9<BP9))*24),"") -> 0 | BU9: =IFERROR(IF(((BT9-BS9+(BT9<BS9))*24)=0,"0",(BT9-BS9+(BT9<BS9))*24),"") -> 0 | BX9: =IFERROR(IF(((BW9-BV9+(BW9<BV9))*24)=0,"0",(BW9-BV9+(BW9<BV9))*24),"") -> 0 | CA9: =IFERROR(IF(((BZ9-BY9+(BZ9<BY9))*24)=0,"0",(BZ9-BY9+(BZ9<BY9))*24),"") -> 0 | CD9: =IFERROR(IF(((CC9-CB9+(CC9<CB9))*24)=0,"0",(CC9-CB9+(CC9<CB9))*24),"") -> 0 | CG9: =IFERROR(IF(((CF9-CE9+(CF9<CE9))*24)=0,"0",(CF9-CE9+(CF9<CE9))*24),"") -> 0 | CJ9: =IFERROR(IF(((CI9-CH9+(CI9<CH9))*24)=0,"0",(CI9-CH9+(CI9<CH9))*24),"") -> 0 | CM9: =IFERROR(IF(((CL9-CK9+(CL9<CK9))*24)=0,"0",(CL9-CK9+(CL9<CK9))*24),"") -> 0 | CP9: =IFERROR(IF(((CO9-CN9+(CO9<CN9))*24)=0,"0",(CO9-CN9+(CO9<CN9))*24),"") -> 0 | CS9: =IFERROR(IF(((CR9-CQ9+(CR9<CQ9))*24)=0,"0",(CR9-CQ9+(CR9<CQ9))*24),"") -> 0 | CV9: =IFERROR(IF(((CU9-CT9+(CU9<CT9))*24)=0,"0",(CU9-CT9+(CU9<CT9))*24),"") -> 0
